Workbook

Sheet ANTIGUO
A1: CONCEPTO | C1: T O T A L | F1: GRUPO DE EDAD (en años) | AN1: Gestantes | AO1: Madre de Hijo menor de 5 años | AP1: Pueblos Originarios | AR1: Migrantes | AT1: Niños, Niñas, Adolescentes y Jóvenes SENAME | AU1: Niños, Niñas, Adolescentes y Jóvenes Mejor Niñez | AV1: Plan Cuidado Integral Elaborado | AW1: TRANS
F2: 0 a 4 años | H2: 5 a 9 años | J2: 10 a 14 años | L2: 15 a 19 años | N2: 20 a 24 años | P2: 25 a 29 años | R2: 30 a 34 años | T2: 35 a 39 años | V2: 40 a 44 años | X2: 45 a 49 años | Z2: 50 a 54 años | AB2: 55 a 59 años | AD2: 60 a 64 años | AF2: 65 a 69 años | AH2: 70 a 74 años | AJ2: 75 a 79 años | AL2: 80 y más años
C3: Ambos sexos | D3: Hombres | E3: Mujeres | F3: Hombres | G3: Mujeres | H3: Hombres | I3: Mujeres | J3: Hombres | K3: Mujeres | L3: Hombres | M3: Mujeres | N3: Hombres | O3: Mujeres | P3: Hombres | Q3: Mujeres | R3: Hombres | S3: Mujeres | T3: Hombres | U3: Mujeres | V3: Hombres | W3: Mujeres | X3: Hombres | Y3: Mujeres | Z3: Hombres | AA3: Mujeres | AB3: Hombres | AC3: Mujeres | AD3: Hombres | AE3: Mujeres | AF3: Hombres | AG3: Mujeres | AH3: Hombres | AI3: Mujeres | AJ3: Hombres | AK3: Mujeres | AL3: Hombres | AM3: Mujeres | AP3: Hombres | AQ3: Mujeres | AR3: Hombres | AS3: Mujeres | AW3: Masculino | AX3: Femenino
A4: NUMERO DE PERSONAS EN CONTROL EN EL PROGRAMA | C4: 1335 | D4: 356 | E4: 979 | F4: 0 | G4: 1 | H4: 20 | I4: 6 | J4: 34 | K4: 34 | L4: 39 | M4: 52 | N4: 16 | O4: 51 | P4: 36 | Q4: 63 | R4: 24 | S4: 77 | T4: 21 | U4: 68 | V4: 15 | W4: 49 | X4: 14 | Y4: 27 | Z4: 16 | AA4: 58 | AB4: 13 | AC4: 117 | AD4: 37 | AE4: 125 | AF4: 27 | AG4: 90 | AH4: 11 | AI4: 62 | AJ4: 20 | AK4: 36 | AL4: 13 | AM4: 63 | AN4: 11 | AO4: 59 | AP4: 19 | AQ4: 37 | AR4: 16 | AS4: 34 | AT4: 2 | AU4: 16 | AV4: 122 | AW4: 16 | AX4: 7
A5: FACTORES DE RIESGO Y CONDICIONANTES DE LA SALUD MENTAL
A6: VIOLENCIA FISICA | B6: VICTIMA | C6: 7 | D6: 0 | E6: 7 | S6: 1 | W6: 2 | AA6: 1 | AE6: 2 | AM6: 1 | AN6: 0 | AO6: 0 | AP6: 0 | AQ6: 1 | AR6: 0 | AS6: 0 | AT6: 0 | AU6: 0 | AV6: 7 | AW6: 0 | AX6: 0
B7: AGRESOR/A | C7: 0 | D7: 0 | E7: 0
A8: VIOLENCIA SEXUAL | B8: VICTIMA | C8: 8 | D8: 1 | E8: 7 | O8: 1 | P8: 1 | Q8: 2 | Y8: 1 | AA8: 1 | AG8: 2 | AN8: 0 | AO8: 0 | AP8: 0 | AQ8: 0 | AR8: 0 | AS8: 1 | AT8: 0 | AU8: 0 | AV8: 3 | AW8: 1 | AX8: 0
B9: AGRESOR/A | C9: 0 | D9: 0 | E9: 0
A10: VIOLENCIA PSICOLOGICA | B10: VICTIMA | C10: 20 | D10: 1 | E10: 19 | M10: 1 | O10: 1 | Q10: 5 | R10: 1 | S10: 2 | U10: 2 | Y10: 2 | AA10: 2 | AC10: 2 | AG10: 2 | AN10: 0 | AO10: 6 | AP10: 0 | AQ10: 4 | AR10: 0 | AS10: 1 | AT10: 0 | AU10: 0 | AV10: 20 | AW10: 1 | AX10: 0
B11: AGRESOR/A | C11: 0 | D11: 0 | E11: 0
A12: ABUSO SEXUAL
A13: SUICIDIO | B13: IDEACIÓN | C13: 6 | D13: 3 | E13: 3 | L13: 1 | N13: 1 | O13: 1 | U13: 2 | Z13: 1 | AN13: 0 | AO13: 1 | AP13: 1 | AQ13: 0 | AR13: 0 | AS13: 1 | AT13: 0 | AU13: 0 | AV13: 6 | AW13: 0 | AX13: 0
B14: INTENTO | C14: 14 | D14: 5 | E14: 9 | K14: 2 | L14: 1 | O14: 1 | T14: 1 | U14: 3 | V14: 1 | W14: 1 | X14: 1 | AA14: 2 | AD14: 1 | AN14: 0 | AO14: 2 | AP14: 0 | AQ14: 0 | AR14: 0 | AS14: 0 | AT14: 0 | AU14: 0 | AV14: 14 | AW14: 0 | AX14: 1
A15: PERSONAS CON DIAGNOSTICOS DE TRASTORNOS MENTALES | C15: 1280 | D15: 346 | E15: 934 | F15: 0 | G15: 1 | H15: 20 | I15: 6 | J15: 34 | K15: 32 | L15: 37 | M15: 51 | N15: 15 | O15: 47 | P15: 35 | Q15: 56 | R15: 23 | S15: 74 | T15: 20 | U15: 61 | V15: 14 | W15: 46 | X15: 13 | Y15: 24 | Z15: 15 | AA15: 52 | AB15: 13 | AC15: 115 | AD15: 36 | AE15: 123 | AF15: 27 | AG15: 86 | AH15: 11 | AI15: 62 | AJ15: 20 | AK15: 36 | AL15: 13 | AM15: 62 | AN15: 11 | AO15: 50 | AP15: 18 | AQ15: 32 | AR15: 16 | AS15: 31 | AT15: 2 | AU15: 16 | AV15: 72 | AW15: 14 | AX15: 6
A16: TRASTORNOS DEL HUMOR (AFECTIVOS) | B16: DEPRESIÓN LEVE | C16: 78 | D16: 9 | E16: 69 | J16: 1 | K16: 1 | M16: 3 | O16: 3 | P16: 2 | Q16: 4 | S16: 6 | T16: 1 | U16: 7 | Y16: 1 | AA16: 4 | AC16: 12 | AD16: 1 | AE16: 7 | AF16: 2 | AG16: 5 | AH16: 1 | AI16: 5 | AK16: 5 | AL16: 1 | AM16: 6 | AN16: 1 | AO16: 8 | AP16: 0 | AQ16: 5 | AR16: 0 | AS16: 1 | AT16: 0 | AU16: 0 | AV16: 0 | AW16: 1 | AX16: 0
B17: DEPRESIÓN MODERADA | C17: 165 | D17: 37 | E17: 128 | J17: 2 | K17: 1 | L17: 5 | M17: 4 | N17: 2 | O17: 3 | P17: 5 | Q17: 9 | R17: 1 | S17: 11 | T17: 5 | U17: 14 | V17: 3 | W17: 12 | X17: 1 | Y17: 3 | Z17: 2 | AA17: 6 | AB17: 3 | AC17: 24 | AD17: 2 | AE17: 14 | AF17: 5 | AG17: 11 | AH17: 1 | AI17: 9 | AK17: 4 | AM17: 3 | AN17: 1 | AO17: 4 | AP17: 1 | AQ17: 5 | AR17: 2 | AS17: 7 | AT17: 0 | AU17: 0 | AV17: 0 | AW17: 1 | AX17: 0
B18: DEPRESIÓN GRAVE | C18: 49 | D18: 18 | E18: 31 | K18: 2 | L18: 2 | M18: 1 | N18: 1 | O18: 1 | P18: 2 | Q18: 3 | R18: 2 | S18: 3 | T18: 1 | U18: 2 | W18: 7 | X18: 2 | Z18: 1 | AA18: 2 | AB18: 1 | AC18: 4 | AD18: 3 | AE18: 3 | AF18: 1 | AG18: 1 | AI18: 1 | AJ18: 2 | AM18: 1 | AN18: 0 | AO18: 3 | AP18: 0 | AQ18: 1 | AR18: 0 | AS18: 2 | AT18: 0 | AU18: 0 | AV18: 0 | AW18: 0 | AX18: 0
B19: DEPRESIÓN POST PARTO | C19: 7 | E19: 7 | O19: 2 | S19: 4 | U19: 1 | AO19: 7 | AQ19: 1 | AS19: 0 | AT19: 0 | AU19: 0 | AV19: 0 | AW19: 1
B20: TRASTORNO BIPOLAR | C20: 14 | D20: 6 | E20: 8 | O20: 1 | Q20: 2 | R20: 1 | S20: 1 | T20: 1 | V20: 1 | Z20: 1 | AA20: 1 | AB20: 1 | AD20: 1 | AE20: 2 | AK20: 1 | AN20: 0 | AO20: 2 | AP20: 0 | AQ20: 0 | AR20: 0 | AS20: 0 | AT20: 0 | AU20: 0 | AV20: 0 | AW20: 0 | AX20: 1
A21: TRASTORNOS MENTALES Y DEL COMPORTAMIENTO DEBIDO A CONSUMO SUSTANCIAS PSICOTROPICAS | B21: CONSUMO PERJUDICIAL DE ALCOHOL | C21: 20 | D21: 13 | E21: 7 | R21: 1 | U21: 3 | V21: 1 | X21: 1 | Y21: 1 | Z21: 2 | AA21: 1 | AC21: 1 | AD21: 4 | AF21: 3 | AG21: 1 | AJ21: 1 | AN21: 0 | AO21: 1 | AP21: 3 | AQ21: 0 | AR21: 0 | AS21: 0 | AT21: 0 | AU21: 0 | AV21: 0 | AW21: 0 | AX21: 0
B22: CONSUMO DEPENDIENTE DEL ALCOHOL | C22: 5 | D22: 3 | E22: 2 | U22: 1 | Y22: 1 | AD22: 2 | AF22: 1 | AN22: 0 | AO22: 0 | AP22: 1 | AQ22: 0 | AR22: 0 | AS22: 0 | AT22: 0 | AU22: 0 | AV22: 0 | AW22: 0 | AX22: 0
B23: CONSUMO PERJUDICIAL DE DROGAS | C23: 16 | D23: 9 | E23: 7 | N23: 1 | P23: 1 | Q23: 2 | R23: 2 | T23: 1 | U23: 1 | W23: 1 | X23: 1 | Y23: 1 | AC23: 1 | AD23: 3 | AK23: 1 | AN23: 0 | AO23: 1 | AP23: 0 | AQ23: 0 | AR23: 0 | AS23: 0 | AT23: 0 | AU23: 0 | AV23: 0 | AW23: 0 | AX23: 0
B24: CONSUMO DEPENDIENTE DE DROGAS | C24: 19 | D24: 9 | E24: 10 | P24: 4 | Q24: 1 | R24: 2 | S24: 2 | U24: 1 | V24: 1 | Z24: 1 | AC24: 2 | AD24: 1 | AI24: 2 | AK24: 1 | AM24: 1 | AN24: 0 | AO24: 0 | AP24: 2 | AQ24: 0 | AR24: 0 | AS24: 0 | AT24: 0 | AU24: 0 | AV24: 0 | AW24: 0 | AX24: 0
B25: CONSUMO DE DROGAS Y ALCOHOL | C25: 15 | D25: 11 | E25: 4 | O25: 1 | P25: 2 | R25: 3 | U25: 3 | X25: 2 | Z25: 2 | AD25: 2 | AN25: 0 | AO25: 0 | AP25: 0 | AQ25: 0 | AR25: 0 | AS25: 0 | AT25: 0 | AU25: 0 | AV25: 0 | AW25: 0 | AX25: 0
A26: TRASTORNOS DEL COMPORTAMIENTO Y DE LAS EMOCIONES DE COMIENZO HABITUAL EN LA INFANCIA Y ADOLESCENCIA | B26: TRASTORNO HIPERCINÉTICO | C26: 87 | D26: 56 | E26: 31 | G26: 1 | H26: 16 | I26: 5 | J26: 20 | K26: 8 | L26: 11 | M26: 2 | N26: 3 | O26: 2 | P26: 1 | Q26: 4 | R26: 3 | S26: 4 | T26: 2 | U26: 3 | AC26: 1 | AE26: 1 | AN26: 0 | AP26: 1 | AQ26: 0 | AR26: 6 | AS26: 1 | AT26: 1 | AU26: 3 | AV26: 0 | AW26: 1 | AX26: 0
B27: TRASTORNO DISOCIAL DESAFIANTE Y OPOSICIONISTA | C27: 1 | D27: 1 | E27: 0 | J27: 1 | AN27: 0 | AP27: 0 | AQ27: 0 | AR27: 0 | AS27: 0 | AT27: 0 | AU27: 0 | AV27: 0 | AW27: 0 | AX27: 0
B28: TRASTORNO DE ANSIEDAD DE SEPARACIÓN EN LA INFANCIA | C28: 0 | D28: 0 | E28: 0 | F28: 0 | G28: 0
B29: OTROS TRASTORNOS DEL COMPORTAMIENTO Y DE LAS EMOCIONES DE COMIENZO HABITUAL EN LA INFANCIA Y ADOLESCENCIA | C29: 28 | D29: 8 | E29: 20 | H29: 2 | J29: 3 | K29: 7 | L29: 3 | M29: 13 | AN29: 0 | AP29: 0 | AQ29: 0 | AR29: 0 | AS29: 1 | AT29: 0 | AU29: 4 | AV29: 0 | AW29: 0 | AX29: 1
A30: TRASTORNOS DE ANSIEDAD | B30: TRASTORNO DE ESTRÉS POST TRAUMATICO | C30: 12 | D30: 0 | E30: 12 | M30: 1 | O30: 1 | Q30: 1 | S30: 1 | W30: 1 | AA30: 3 | AC30: 2 | AE30: 2 | AN30: 1 | AO30: 1 | AP30: 0 | AQ30: 1 | AR30: 0 | AS30: 0 | AT30: 0 | AU30: 0 | AV30: 0 | AW30: 0 | AX30: 0
B31: TRASTORNO DE PÁNICO | C31: 23 | D31: 2 | E31: 21 | M31: 1 | O31: 2 | P31: 1 | Q31: 2 | S31: 6 | U31: 1 | W31: 1 | Z31: 1 | AC31: 4 | AE31: 2 | AG31: 2 | AN31: 2 | AO31: 3 | AP31: 0 | AQ31: 1 | AR31: 0 | AS31: 1 | AT31: 0 | AU31: 0 | AV31: 0 | AW31: 0 | AX31: 0
B32: FOBIAS SOCIALES | C32: 5 | D32: 3 | E32: 2 | L32: 2 | O32: 2 | P32: 1 | AN32: 0 | AO32: 0 | AP32: 0 | AQ32: 1 | AR32: 0 | AS32: 0 | AT32: 0 | AU32: 1 | AV32: 0 | AW32: 0 | AX32: 0
B33: TRASTORNOS DE ANSIEDAD GENERALIZADA | C33: 53 | D33: 14 | E33: 39 | K33: 1 | L33: 1 | O33: 3 | P33: 2 | Q33: 6 | R33: 2 | S33: 3 | T33: 1 | U33: 4 | V33: 1 | W33: 4 | X33: 1 | Y33: 1 | Z33: 1 | AA33: 2 | AB33: 1 | AC33: 4 | AD33: 2 | AE33: 5 | AF33: 2 | AG33: 3 | AI33: 3 | AN33: 0 | AO33: 2 | AP33: 0 | AQ33: 1 | AR33: 1 | AS33: 0 | AT33: 0 | AU33: 0 | AV33: 0 | AW33: 2 | AX33: 0
B34: OTROS TRASTORNOS DE ANSIEDAD | C34: 99 | D34: 23 | E34: 76 | J34: 1 | K34: 0 | L34: 2 | M34: 5 | N34: 0 | O34: 3 | P34: 3 | Q34: 7 | R34: 2 | S34: 6 | T34: 2 | U34: 3 | V34: 1 | W34: 2 | X34: 2 | Y34: 4 | AA34: 4 | AB34: 1 | AC34: 8 | AD34: 1 | AE34: 14 | AF34: 4 | AG34: 9 | AH34: 2 | AI34: 4 | AJ34: 1 | AK34: 3 | AL34: 1 | AM34: 4 | AN34: 1 | AO34: 3 | AP34: 2 | AQ34: 5 | AR34: 2 | AS34: 3 | AT34: 0 | AU34: 0 | AV34: 0 | AW34: 1 | AX34: 2
A35: DEMENCIAS (INCLUYE ALZHEIMER) | B35: LEVE | C35: 21 | D35: 6 | E35: 15 | AD35: 1 | AF35: 2 | AG35: 3 | AI35: 5 | AJ35: 2 | AK35: 2 | AL35: 1 | AM35: 5 | AP35: 0 | AQ35: 1 | AR35: 0 | AS35: 0 | AV35: 21 | AW35: 1 | AX35: 0
B36: MODERADO | C36: 35 | D36: 10 | E36: 25 | AD36: 2 | AF36: 1 | AJ36: 3 | AK36: 2 | AL36: 4 | AM36: 23 | AP36: 0 | AQ36: 0 | AR36: 0 | AS36: 0 | AV36: 35 | AW36: 0 | AX36: 0
B37: AVANZADO | C37: 16 | D37: 7 | E37: 9 | AD37: 2 | AJ37: 1 | AK37: 3 | AL37: 4 | AM37: 6 | AP37: 0 | AQ37: 0 | AR37: 0 | AS37: 0 | AV37: 16 | AW37: 0 | AX37: 0
A38: ESQUIZOFRENIA | C38: 0 | D38: 0 | E38: 0 | F38: 0 | G38: 0
A39: TRASTORNO ADAPTATIVO | C39: 152 | D39: 21 | E39: 131 | I39: 1 | J39: 1 | K39: 4 | L39: 1 | M39: 3 | N39: 1 | O39: 1 | Q39: 1 | S39: 10 | T39: 0 | U39: 7 | V39: 2 | W39: 5 | Y39: 4 | Z39: 1 | AA39: 12 | AB39: 2 | AC39: 15 | AD39: 3 | AE39: 28 | AF39: 2 | AG39: 16 | AH39: 1 | AI39: 13 | AJ39: 6 | AK39: 6 | AL39: 1 | AM39: 5 | AN39: 2 | AO39: 3 | AP39: 5 | AQ39: 1 | AR39: 4 | AS39: 6 | AT39: 1 | AU39: 4 | AV39: 0 | AW39: 2 | AX39: 1
A40: TRASTORNOS DE LA CONDUCTA ALIMENTARIA | C40: 4 | D40: 0 | E40: 4 | M40: 2 | O40: 2 | AN40: 0 | AO40: 0 | AP40: 0 | AQ40: 0 | AR40: 0 | AS40: 1 | AT40: 0 | AU40: 0 | AV40: 0 | AW40: 0 | AX40: 0
...

Sheet NUEVO
A1: CONCEPTO | C1: T O T A L | F1: GRUPO DE EDAD (en años) | AN1: Gestantes | AO1: Madre de Hijo menor de 5 años | AP1: Pueblos Originarios | AR1: Migrantes | AT1: Niños, Niñas, Adolescentes y Jóvenes SENAME | AU1: Niños, Niñas, Adolescentes y Jóvenes Mejor Niñez | AV1: Plan Cuidado Integral Elaborado | AW1: TRANS
F2: 0 a 4 años | H2: 5 a 9 años | J2: 10 a 14 años | L2: 15 a 19 años | N2: 20 a 24 años | P2: 25 a 29 años | R2: 30 a 34 años | T2: 35 a 39 años | V2: 40 a 44 años | X2: 45 a 49 años | Z2: 50 a 54 años | AB2: 55 a 59 años | AD2: 60 a 64 años | AF2: 65 a 69 años | AH2: 70 a 74 años | AJ2: 75 a 79 años | AL2: 80 y más años
C3: Ambos sexos | D3: Hombres | E3: Mujeres | F3: Hombres | G3: Mujeres | H3: Hombres | I3: Mujeres | J3: Hombres | K3: Mujeres | L3: Hombres | M3: Mujeres | N3: Hombres | O3: Mujeres | P3: Hombres | Q3: Mujeres | R3: Hombres | S3: Mujeres | T3: Hombres | U3: Mujeres | V3: Hombres | W3: Mujeres | X3: Hombres | Y3: Mujeres | Z3: Hombres | AA3: Mujeres | AB3: Hombres | AC3: Mujeres | AD3: Hombres | AE3: Mujeres | AF3: Hombres | AG3: Mujeres | AH3: Hombres | AI3: Mujeres | AJ3: Hombres | AK3: Mujeres | AL3: Hombres | AM3: Mujeres | AP3: Hombres | AQ3: Mujeres | AR3: Hombres | AS3: Mujeres | AW3: Masculino | AX3: Femenino
A4: NUMERO DE PERSONAS EN CONTROL EN EL PROGRAMA | C4: 1320 | D4: 329 | E4: 991 | F4: 0 | G4: 1 | H4: 20 | I4: 5 | J4: 30 | K4: 30 | L4: 33 | M4: 63 | N4: 16 | O4: 38 | P4: 33 | Q4: 69 | R4: 22 | S4: 74 | T4: 18 | U4: 73 | V4: 14 | W4: 40 | X4: 10 | Y4: 36 | Z4: 10 | AA4: 58 | AB4: 16 | AC4: 110 | AD4: 23 | AE4: 136 | AF4: 27 | AG4: 94 | AH4: 18 | AI4: 61 | AJ4: 21 | AK4: 42 | AL4: 18 | AM4: 61 | AN4: 11 | AO4: 87 | AP4: 11 | AQ4: 38 | AR4: 14 | AS4: 30 | AT4: 0 | AU4: 10 | AV4: 74 | AW4: 15 | AX4: 4
A5: FACTORES DE RIESGO Y CONDICIONANTES DE LA SALUD MENTAL
A6: VIOLENCIA | B6: VICTIMA | C6: 7 | D6: 0 | E6: 7 | F6: 0 | G6: 0 | H6: 0 | I6: 0 | J6: 0 | K6: 0 | L6: 0 | M6: 0 | N6: 0 | O6: 0 | P6: 0 | Q6: 0 | R6: 0 | S6: 1 | T6: 0 | U6: 0 | V6: 0 | W6: 2 | X6: 0 | Y6: 0 | Z6: 0 | AA6: 1 | AB6: 0 | AC6: 0 | AD6: 0 | AE6: 2 | AF6: 0 | AG6: 0 | AH6: 0 | AI6: 0 | AJ6: 0 | AK6: 0 | AL6: 0 | AM6: 1 | AN6: 0 | AO6: 0 | AP6: 0 | AQ6: 1 | AR6: 0 | AS6: 0 | AT6: 0 | AU6: 0 | AV6: 7 | AW6: 0 | AX6: 0
B7: AGRESOR/A | C7: 0 | D7: 0 | E7: 0
C8: 8 | D8: 1 | E8: 7 | F8: 0 | G8: 0 | H8: 0 | I8: 0 | J8: 0 | K8: 0 | L8: 0 | M8: 0 | N8: 0 | O8: 1 | P8: 1 | Q8: 2 | R8: 0 | S8: 0 | T8: 0 | U8: 0 | V8: 0 | W8: 0 | X8: 0 | Y8: 1 | Z8: 0 | AA8: 1 | AB8: 0 | AC8: 0 | AD8: 0 | AE8: 0 | AF8: 0 | AG8: 2 | AH8: 0 | AI8: 0 | AJ8: 0 | AK8: 0 | AL8: 0 | AM8: 0 | AN8: 0 | AO8: 0 | AP8: 0 | AQ8: 1 | AR8: 0 | AS8: 0 | AT8: 0 | AU8: 0 | AV8: 8 | AW8: 1 | AX8: 0
C9: 0 | D9: 0 | E9: 0
C10: 20 | D10: 1 | E10: 19 | F10: 0 | G10: 0 | H10: 0 | I10: 0 | J10: 0 | K10: 0 | L10: 0 | M10: 1 | N10: 0 | O10: 1 | P10: 0 | Q10: 5 | R10: 1 | S10: 2 | T10: 0 | U10: 2 | V10: 0 | W10: 0 | X10: 0 | Y10: 2 | Z10: 0 | AA10: 2 | AB10: 0 | AC10: 2 | AD10: 0 | AE10: 0 | AF10: 0 | AG10: 2 | AH10: 0 | AI10: 0 | AJ10: 0 | AK10: 0 | AL10: 0 | AM10: 0 | AN10: 0 | AO10: 6 | AP10: 0 | AQ10: 4 | AR10: 0 | AS10: 1 | AT10: 0 | AU10: 0 | AV10: 20 | AW10: 1 | AX10: 0
C11: 0 | D11: 0 | E11: 0
A12: ABUSO SEXUAL
A13: SUICIDIO | B13: IDEACIÓN | C13: 4 | D13: 2 | E13: 2 | H13: 0 | I13: 0 | J13: 0 | K13: 0 | L13: 1 | M13: 0 | N13: 1 | O13: 1 | P13: 0 | Q13: 0 | R13: 0 | S13: 0 | T13: 0 | U13: 1 | V13: 0 | W13: 0 | X13: 0 | Y13: 0 | Z13: 0 | AA13: 0 | AB13: 0 | AC13: 0 | AD13: 0 | AE13: 0 | AF13: 0 | AG13: 0 | AH13: 0 | AI13: 0 | AJ13: 0 | AK13: 0 | AL13: 0 | AM13: 0 | AN13: 1 | AO13: 0 | AP13: 0 | AQ13: 0 | AR13: 0 | AS13: 1 | AT13: 0 | AU13: 0 | AV13: 4 | AW13: 0 | AX13: 0
B14: INTENTO | C14: 15 | D14: 4 | E14: 11 | H14: 0 | I14: 0 | J14: 0 | K14: 2 | L14: 1 | M14: 1 | N14: 0 | O14: 1 | P14: 0 | Q14: 0 | R14: 0 | S14: 0 | T14: 0 | U14: 3 | V14: 1 | W14: 1 | X14: 1 | Y14: 0 | Z14: 0 | AA14: 3 | AB14: 0 | AC14: 0 | AD14: 0 | AE14: 0 | AF14: 1 | AG14: 0 | AH14: 0 | AI14: 0 | AJ14: 0 | AK14: 0 | AL14: 0 | AM14: 0 | AN14: 2 | AO14: 0 | AP14: 0 | AQ14: 0 | AR14: 0 | AS14: 0 | AT14: 0 | AU14: 0 | AV14: 15 | AW14: 0 | AX14: 1
A15: PERSONAS CON DIAGNOSTICOS DE TRASTORNOS MENTALES | C15: 1290 | D15: 327 | E15: 963 | F15: 0 | G15: 1 | H15: 20 | I15: 5 | J15: 30 | K15: 30 | L15: 33 | M15: 62 | N15: 16 | O15: 36 | P15: 32 | Q15: 62 | R15: 21 | S15: 71 | T15: 18 | U15: 72 | V15: 14 | W15: 38 | X15: 10 | Y15: 34 | Z15: 10 | AA15: 54 | AB15: 16 | AC15: 110 | AD15: 23 | AE15: 134 | AF15: 27 | AG15: 91 | AH15: 18 | AI15: 61 | AJ15: 21 | AK15: 42 | AL15: 18 | AM15: 60 | AN15: 11 | AO15: 87 | AP15: 11 | AQ15: 38 | AR15: 14 | AS15: 30 | AT15: 0 | AU15: 10 | AV15: 74 | AW15: 15 | AX15: 4
A16: TRASTORNOS DEL HUMOR (AFECTIVOS) | B16: DEPRESIÓN LEVE | C16: 82 | D16: 10 | E16: 72 | F16: 0 | G16: 0 | H16: 0 | I16: 0 | J16: 1 | K16: 1 | L16: 0 | M16: 4 | N16: 0 | O16: 3 | P16: 3 | Q16: 4 | R16: 0 | S16: 6 | T16: 1 | U16: 8 | V16: 0 | W16: 0 | X16: 0 | Y16: 2 | Z16: 0 | AA16: 4 | AB16: 0 | AC16: 10 | AD16: 1 | AE16: 8 | AF16: 2 | AG16: 6 | AH16: 1 | AI16: 6 | AJ16: 0 | AK16: 5 | AL16: 1 | AM16: 5 | AN16: 0 | AO16: 10 | AP16: 0 | AQ16: 5 | AR16: 0 | AS16: 1 | AT16: 0 | AU16: 0 | AV16: 0 | AW16: 1 | AX16: 0
B17: DEPRESIÓN MODERADA | C17: 185 | D17: 40 | E17: 145 | F17: 0 | G17: 0 | H17: 0 | I17: 0 | J17: 2 | K17: 1 | L17: 6 | M17: 5 | N17: 2 | O17: 5 | P17: 4 | Q17: 11 | R17: 2 | S17: 12 | T17: 5 | U17: 16 | V17: 2 | W17: 12 | X17: 2 | Y17: 5 | Z17: 2 | AA17: 8 | AB17: 3 | AC17: 26 | AD17: 3 | AE17: 17 | AF17: 5 | AG17: 12 | AH17: 1 | AI17: 8 | AJ17: 0 | AK17: 4 | AL17: 1 | AM17: 3 | AN17: 1 | AO17: 22 | AP17: 1 | AQ17: 6 | AR17: 2 | AS17: 7 | AT17: 0 | AU17: 0 | AV17: 0 | AW17: 1 | AX17: 0
B18: DEPRESIÓN GRAVE | C18: 54 | D18: 18 | E18: 36 | F18: 0 | G18: 0 | H18: 0 | I18: 0 | J18: 0 | K18: 2 | L18: 2 | M18: 3 | N18: 1 | O18: 1 | P18: 2 | Q18: 4 | R18: 2 | S18: 3 | T18: 0 | U18: 3 | V18: 0 | W18: 6 | X18: 2 | Y18: 1 | Z18: 1 | AA18: 2 | AB18: 2 | AC18: 4 | AD18: 2 | AE18: 4 | AF18: 2 | AG18: 1 | AH18: 0 | AI18: 1 | AJ18: 2 | AK18: 0 | AL18: 0 | AM18: 1 | AN18: 0 | AO18: 3 | AP18: 0 | AQ18: 2 | AR18: 0 | AS18: 2 | AT18: 0 | AU18: 1 | AV18: 1 | AW18: 0 | AX18: 0
B19: DEPRESIÓN POST PARTO | C19: 7 | E19: 7 | O19: 2 | S19: 4 | U19: 1 | AO19: 7 | AQ19: 1 | AS19: 0 | AT19: 0 | AU19: 0 | AV19: 0 | AW19: 1
B20: TRASTORNO BIPOLAR | C20: 17 | D20: 7 | E20: 10 | F20: 0 | G20: 0 | H20: 0 | I20: 0 | J20: 0 | K20: 0 | L20: 0 | M20: 0 | N20: 1 | O20: 1 | P20: 0 | Q20: 2 | R20: 1 | S20: 1 | T20: 1 | U20: 1 | V20: 1 | W20: 0 | X20: 0 | Y20: 0 | Z20: 1 | AA20: 1 | AB20: 1 | AC20: 1 | AD20: 1 | AE20: 2 | AF20: 0 | AG20: 0 | AH20: 0 | AI20: 0 | AJ20: 0 | AK20: 1 | AL20: 0 | AM20: 0 | AN20: 0 | AO20: 2 | AP20: 0 | AQ20: 0 | AR20: 0 | AS20: 0 | AT20: 0 | AU20: 0 | AV20: 0 | AW20: 0 | AX20: 1
A21: TRASTORNOS MENTALES Y DEL COMPORTAMIENTO DEBIDO A CONSUMO SUSTANCIAS PSICOTROPICAS | B21: CONSUMO PERJUDICIAL DE ALCOHOL | C21: 20 | D21: 13 | E21: 7 | F21: 0 | G21: 0 | H21: 0 | I21: 0 | J21: 0 | K21: 0 | L21: 0 | M21: 0 | N21: 1 | O21: 0 | P21: 0 | Q21: 0 | R21: 1 | S21: 0 | T21: 0 | U21: 3 | V21: 1 | W21: 0 | X21: 1 | Y21: 1 | Z21: 1 | AA21: 1 | AB21: 0 | AC21: 1 | AD21: 4 | AE21: 0 | AF21: 3 | AG21: 1 | AH21: 0 | AI21: 0 | AJ21: 1 | AK21: 0 | AL21: 0 | AM21: 0 | AN21: 0 | AO21: 1 | AP21: 2 | AQ21: 0 | AR21: 0 | AS21: 0 | AT21: 0 | AU21: 0 | AV21: 0 | AW21: 0 | AX21: 0
B22: CONSUMO DEPENDIENTE DEL ALCOHOL | C22: 6 | D22: 5 | E22: 1 | F22: 0 | G22: 0 | H22: 0 | I22: 0 | J22: 0 | K22: 0 | L22: 0 | M22: 0 | N22: 1 | O22: 0 | P22: 0 | Q22: 0 | R22: 0 | S22: 0 | T22: 0 | U22: 0 | V22: 0 | W22: 0 | X22: 0 | Y22: 1 | Z22: 0 | AA22: 0 | AB22: 1 | AC22: 0 | AD22: 2 | AE22: 0 | AF22: 1 | AG22: 0 | AH22: 0 | AI22: 0 | AJ22: 0 | AK22: 0 | AL22: 0 | AM22: 0 | AN22: 0 | AO22: 0 | AP22: 1 | AQ22: 0 | AR22: 0 | AS22: 0 | AT22: 0 | AU22: 0 | AV22: 0 | AW22: 0 | AX22: 0
B23: CONSUMO PERJUDICIAL DE DROGAS | C23: 19 | D23: 12 | E23: 7 | F23: 0 | G23: 0 | H23: 0 | I23: 0 | J23: 0 | K23: 0 | L23: 0 | M23: 0 | N23: 2 | O23: 0 | P23: 2 | Q23: 2 | R23: 2 | S23: 0 | T23: 1 | U23: 1 | V23: 0 | W23: 1 | X23: 1 | Y23: 1 | Z23: 0 | AA23: 0 | AB23: 1 | AC23: 1 | AD23: 3 | AE23: 0 | AF23: 0 | AG23: 0 | AH23: 0 | AI23: 0 | AJ23: 0 | AK23: 1 | AL23: 0 | AM23: 0 | AN23: 0 | AO23: 1 | AP23: 2 | AQ23: 0 | AR23: 0 | AS23: 0 | AT23: 0 | AU23: 0 | AV23: 0 | AW23: 0 | AX23: 0
B24: CONSUMO DEPENDIENTE DE DROGAS | C24: 21 | D24: 10 | E24: 11 | F24: 0 | G24: 0 | H24: 0 | I24: 0 | J24: 0 | K24: 0 | L24: 0 | M24: 0 | N24: 1 | O24: 0 | P24: 4 | Q24: 1 | R24: 2 | S24: 3 | T24: 0 | U24: 1 | V24: 2 | W24: 0 | X24: 0 | Y24: 0 | Z24: 0 | AA24: 0 | AB24: 0 | AC24: 2 | AD24: 1 | AE24: 0 | AF24: 0 | AG24: 0 | AH24: 0 | AI24: 2 | AJ24: 0 | AK24: 1 | AL24: 0 | AM24: 1 | AN24: 0 | AO24: 0 | AP24: 1 | AQ24: 0 | AR24: 0 | AS24: 0 | AT24: 0 | AU24: 0 | AV24: 0 | AW24: 0 | AX24: 0
B25: CONSUMO DE DROGAS Y ALCOHOL | C25: 14 | D25: 10 | E25: 4 | F25: 0 | G25: 0 | H25: 0 | I25: 0 | J25: 0 | K25: 0 | L25: 0 | M25: 0 | N25: 1 | O25: 1 | P25: 2 | Q25: 0 | R25: 3 | S25: 0 | T25: 0 | U25: 2 | V25: 0 | W25: 0 | X25: 1 | Y25: 0 | Z25: 1 | AA25: 1 | AB25: 0 | AC25: 0 | AD25: 2 | AE25: 0 | AF25: 0 | AG25: 0 | AH25: 0 | AI25: 0 | AJ25: 0 | AK25: 0 | AL25: 0 | AM25: 0 | AN25: 0 | AO25: 0 | AP25: 0 | AQ25: 0 | AR25: 0 | AS25: 0 | AT25: 0 | AU25: 0 | AV25: 0 | AW25: 0 | AX25: 0
A26: TRASTORNOS DEL COMPORTAMIENTO Y DE LAS EMOCIONES DE COMIENZO HABITUAL EN LA INFANCIA Y ADOLESCENCIA | B26: TRASTORNO HIPERCINÉTICO | C26: 94 | D26: 59 | E26: 35 | F26: 0 | G26: 1 | H26: 18 | I26: 5 | J26: 20 | K26: 9 | L26: 10 | M26: 3 | N26: 3 | O26: 2 | P26: 1 | Q26: 6 | R26: 4 | S26: 3 | T26: 3 | U26: 3 | V26: 0 | W26: 0 | X26: 0 | Y26: 1 | Z26: 0 | AA26: 0 | AB26: 0 | AC26: 1 | AD26: 0 | AE26: 1 | AF26: 0 | AG26: 0 | AH26: 0 | AI26: 0 | AJ26: 0 | AK26: 0 | AL26: 0 | AM26: 0 | AN26: 0 | AP26: 1 | AQ26: 0 | AR26: 6 | AS26: 1 | AT26: 0 | AU26: 4 | AV26: 0 | AW26: 1 | AX26: 0
B27: TRASTORNO DISOCIAL DESAFIANTE Y OPOSICIONISTA | C27: 2 | D27: 1 | E27: 1 | F27: 0 | G27: 0 | H27: 0 | I27: 0 | J27: 1 | K27: 1 | L27: 0 | M27: 0 | N27: 0 | O27: 0 | P27: 0 | Q27: 0 | R27: 0 | S27: 0 | T27: 0 | U27: 0 | V27: 0 | W27: 0 | X27: 0 | Y27: 0 | Z27: 0 | AA27: 0 | AB27: 0 | AC27: 0 | AD27: 0 | AE27: 0 | AF27: 0 | AG27: 0 | AH27: 0 | AI27: 0 | AJ27: 0 | AK27: 0 | AL27: 0 | AM27: 0 | AN27: 0 | AP27: 0 | AQ27: 0 | AR27: 0 | AS27: 0 | AT27: 0 | AU27: 0 | AV27: 0 | AW27: 0 | AX27: 0
B28: TRASTORNO DE ANSIEDAD DE SEPARACIÓN EN LA INFANCIA | C28: 0 | D28: 0 | E28: 0 | F28: 0 | G28: 0
B29: OTROS TRASTORNOS DEL COMPORTAMIENTO Y DE LAS EMOCIONES DE COMIENZO HABITUAL EN LA INFANCIA Y ADOLESCENCIA | C29: 29 | D29: 7 | E29: 22 | F29: 0 | G29: 0 | H29: 2 | I29: 0 | J29: 3 | K29: 7 | L29: 2 | M29: 15 | N29: 0 | O29: 0 | AN29: 0 | AP29: 0 | AQ29: 0 | AR29: 0 | AS29: 1 | AT29: 0 | AU29: 5 | AV29: 0 | AW29: 0 | AX29: 1
A30: TRASTORNOS DE ANSIEDAD | B30: TRASTORNO DE ESTRÉS POST TRAUMATICO | C30: 13 | D30: 1 | E30: 12 | F30: 0 | G30: 0 | H30: 0 | I30: 0 | J30: 1 | K30: 0 | L30: 0 | M30: 1 | N30: 0 | O30: 1 | P30: 0 | Q30: 1 | R30: 0 | S30: 1 | T30: 0 | U30: 0 | V30: 0 | W30: 1 | X30: 0 | Y30: 0 | Z30: 0 | AA30: 3 | AB30: 0 | AC30: 2 | AD30: 0 | AE30: 2 | AF30: 0 | AG30: 0 | AH30: 0 | AI30: 0 | AJ30: 0 | AK30: 0 | AL30: 0 | AM30: 0 | AN30: 1 | AO30: 1 | AP30: 0 | AQ30: 1 | AR30: 1 | AS30: 0 | AT30: 0 | AU30: 0 | AV30: 0 | AW30: 0 | AX30: 0
B31: TRASTORNO DE PÁNICO | C31: 27 | D31: 3 | E31: 24 | F31: 0 | G31: 0 | H31: 0 | I31: 0 | J31: 1 | K31: 0 | L31: 0 | M31: 2 | N31: 0 | O31: 2 | P31: 1 | Q31: 2 | R31: 0 | S31: 6 | T31: 0 | U31: 1 | V31: 0 | W31: 1 | X31: 0 | Y31: 1 | Z31: 1 | AA31: 0 | AB31: 0 | AC31: 4 | AD31: 0 | AE31: 3 | AF31: 0 | AG31: 2 | AH31: 0 | AI31: 0 | AJ31: 0 | AK31: 0 | AL31: 0 | AM31: 0 | AN31: 1 | AO31: 3 | AP31: 0 | AQ31: 1 | AR31: 0 | AS31: 1 | AT31: 0 | AU31: 0 | AV31: 0 | AW31: 0 | AX31: 0
B32: FOBIAS SOCIALES | C32: 5 | D32: 3 | E32: 2 | F32: 0 | G32: 0 | H32: 0 | I32: 0 | J32: 0 | K32: 0 | L32: 2 | M32: 0 | N32: 0 | O32: 2 | P32: 1 | Q32: 0 | R32: 0 | S32: 0 | T32: 0 | U32: 0 | V32: 0 | W32: 0 | X32: 0 | Y32: 0 | Z32: 0 | AA32: 0 | AB32: 0 | AC32: 0 | AD32: 0 | AE32: 0 | AF32: 0 | AG32: 0 | AH32: 0 | AI32: 0 | AJ32: 0 | AK32: 0 | AL32: 0 | AM32: 0 | AN32: 1 | AO32: 1 | AP32: 1 | AQ32: 1 | AR32: 1 | AS32: 1 | AT32: 1 | AU32: 1 | AV32: 1 | AW32: 1 | AX32: 1
B33: TRASTORNOS DE ANSIEDAD GENERALIZADA | C33: 52 | D33: 13 | E33: 39 | F33: 0 | G33: 0 | H33: 0 | I33: 0 | J33: 0 | K33: 1 | L33: 1 | M33: 0 | N33: 0 | O33: 3 | P33: 2 | Q33: 6 | R33: 2 | S33: 2 | T33: 1 | U33: 5 | V33: 0 | W33: 4 | X33: 1 | Y33: 2 | Z33: 1 | AA33: 1 | AB33: 1 | AC33: 3 | AD33: 2 | AE33: 6 | AF33: 2 | AG33: 3 | AH33: 0 | AI33: 3 | AJ33: 0 | AK33: 0 | AL33: 0 | AM33: 0 | AN33: 0 | AO33: 2 | AP33: 0 | AQ33: 1 | AR33: 1 | AS33: 0 | AT33: 0 | AU33: 0 | AV33: 0 | AW33: 2 | AX33: 0
B34: OTROS TRASTORNOS DE ANSIEDAD | C34: 414 | D34: 84 | E34: 330 | F34: 0 | G34: 0 | H34: 0 | I34: 0 | J34: 2 | K34: 5 | L34: 8 | M34: 23 | N34: 4 | O34: 15 | P34: 15 | Q34: 29 | R34: 5 | S34: 23 | T34: 6 | U34: 30 | V34: 5 | W34: 11 | X34: 3 | Y34: 16 | Z34: 3 | AA34: 17 | AB34: 7 | AC34: 34 | AD34: 3 | AE34: 48 | AF34: 10 | AG34: 37 | AH34: 7 | AI34: 18 | AJ34: 4 | AK34: 16 | AL34: 2 | AM34: 8 | AN34: 4 | AO34: 31 | AP34: 3 | AQ34: 14 | AR34: 6 | AS34: 8 | AT34: 0 | AU34: 1 | AV34: 0 | AW34: 4 | AX34: 2
A35: DEMENCIAS (INCLUYE ALZHEIMER) | B35: LEVE | C35: 21 | D35: 6 | E35: 15 | R35: 0 | S35: 0 | T35: 0 | U35: 0 | V35: 0 | W35: 0 | X35: 0 | Y35: 0 | Z35: 0 | AA35: 0 | AB35: 0 | AC35: 0 | AD35: 1 | AE35: 0 | AF35: 1 | AG35: 3 | AH35: 1 | AI35: 5 | AJ35: 2 | AK35: 2 | AL35: 1 | AM35: 5 | AP35: 0 | AQ35: 1 | AR35: 0 | AS35: 0 | AV35: 21 | AW35: 1 | AX35: 0
B36: MODERADO | C36: 35 | D36: 12 | E36: 23 | R36: 0 | S36: 0 | T36: 0 | U36: 0 | V36: 0 | W36: 0 | X36: 1 | Y36: 0 | Z36: 0 | AA36: 0 | AB36: 0 | AC36: 0 | AD36: 0 | AE36: 0 | AF36: 2 | AG36: 0 | AH36: 0 | AI36: 0 | AJ36: 3 | AK36: 2 | AL36: 6 | AM36: 21 | AP36: 0 | AQ36: 0 | AR36: 0 | AS36: 0 | AV36: 35 | AW36: 0 | AX36: 0
B37: AVANZADO | C37: 16 | D37: 7 | E37: 9 | R37: 0 | S37: 0 | T37: 0 | U37: 0 | V37: 0 | W37: 0 | X37: 0 | Y37: 0 | Z37: 0 | AA37: 0 | AB37: 0 | AC37: 0 | AD37: 2 | AE37: 0 | AF37: 0 | AG37: 0 | AH37: 0 | AI37: 0 | AJ37: 1 | AK37: 3 | AL37: 4 | AM37: 6 | AP37: 0 | AQ37: 0 | AR37: 0 | AS37: 0 | AV37: 16 | AW37: 0 | AX37: 0
A38: ESQUIZOFRENIA | C38: 0 | D38: 0 | E38: 0 | F38: 0 | G38: 0
A39: TRASTORNO ADAPTATIVO | C39: 277 | D39: 45 | E39: 232 | F39: 0 | G39: 0 | H39: 0 | I39: 1 | J39: 4 | K39: 4 | L39: 3 | M39: 7 | N39: 1 | O39: 4 | P39: 2 | Q39: 7 | R39: 2 | S39: 16 | T39: 1 | U39: 19 | V39: 2 | W39: 7 | X39: 0 | Y39: 8 | Z39: 2 | AA39: 18 | AB39: 2 | AC39: 27 | AD39: 6 | AE39: 42 | AF39: 4 | AG39: 28 | AH39: 4 | AI39: 18 | AJ39: 7 | AK39: 14 | AL39: 5 | AM39: 12 | AN39: 3 | AO39: 27 | AP39: 2 | AQ39: 12 | AR39: 1 | AS39: 6 | AT39: 0 | AU39: 1 | AV39: 0 | AW39: 1 | AX39: 0
A40: TRASTORNOS DE LA CONDUCTA ALIMENTARIA | C40: 5 | D40: 0 | E40: 5 | F40: 0 | G40: 0 | H40: 0 | I40: 0 | J40: 0 | K40: 0 | L40: 0 | M40: 2 | N40: 0 | O40: 2 | P40: 0 | Q40: 0 | R40: 0 | S40: 0 | T40: 0 | U40: 0 | V40: 0 | W40: 0 | X40: 0 | Y40: 0 | Z40: 0 | AA40: 0 | AB40: 0 | AC40: 1 | AD40: 0 | AE40: 0 | AF40: 0 | AG40: 0 | AH40: 0 | AI40: 0 | AJ40: 0 | AK40: 0 | AL40: 0 | AM40: 0 | AN40: 0 | AO40: 0 | AP40: 0 | AQ40: 0 | AR40: 0 | AS40: 1 | AT40: 0 | AU40: 0 | AV40: 0 | AW40: 0 | AX40: 0
...

Sheet ALTAS
A1: CONCEPTO
C3: esto es lo que no aparece en el A
A4: NUMERO DE PERSONAS EN CONTROL EN EL PROGRAMA | C4: altas clinicas demostrables por formulario | D4: fallecidos | E4: traslado
A5: FACTORES DE RIESGO Y CONDICIONANTES DE LA SALUD MENTAL
A6: VIOLENCIA FISICA | B6: VICTIMA
B7: AGRESOR/A
A8: VIOLENCIA SEXUAL | B8: VICTIMA
B9: AGRESOR/A
A10: VIOLENCIA PSICOLOGICA | B10: VICTIMA
B11: AGRESOR/A
A12: ABUSO SEXUAL
A13: SUICIDIO | B13: IDEACIÓN
B14: INTENTO
A15: PERSONAS CON DIAGNOSTICOS DE TRASTORNOS MENTALES
A16: TRASTORNOS DEL HUMOR (AFECTIVOS) | B16: DEPRESIÓN LEVE | C16: 3
B17: DEPRESIÓN MODERADA | C17: 3
B18: DEPRESIÓN GRAVE | C18: 2
B19: DEPRESIÓN POST PARTO
B20: TRASTORNO BIPOLAR | D20: 0
A21: DIFERENCIA FORMATO ENTRE A Y P
A24: TRASTORNOS MENTALES Y DEL COMPORTAMIENTO DEBIDO A CONSUMO SUSTANCIAS PSICOTROPICAS | B24: CONSUMO PERJUDICIAL DE ALCOHOL | E24: 1
B25: CONSUMO DEPENDIENTE DEL ALCOHOL
B26: CONSUMO PERJUDICIAL DE DROGAS
B27: CONSUMO DEPENDIENTE DE DROGAS
B28: CONSUMO DE DROGAS Y ALCOHOL | E28: 1
A29: TRASTORNOS DEL COMPORTAMIENTO Y DE LAS EMOCIONES DE COMIENZO HABITUAL EN LA INFANCIA Y ADOLESCENCIA | B29: TRASTORNO HIPERCINÉTICO
B30: TRASTORNO DISOCIAL DESAFIANTE Y OPOSICIONISTA
B31: TRASTORNO DE ANSIEDAD DE SEPARACIÓN EN LA INFANCIA
B32: OTROS TRASTORNOS DEL COMPORTAMIENTO Y DE LAS EMOCIONES DE COMIENZO HABITUAL EN LA INFANCIA Y ADOLESCENCIA
A33: TRASTORNOS DE ANSIEDAD | B33: TRASTORNO DE ESTRÉS POST TRAUMATICO
B34: TRASTORNO DE PÁNICO
B35: FOBIAS SOCIALES
B36: TRASTORNOS DE ANSIEDAD GENERALIZADA | C36: 1
B37: OTROS TRASTORNOS DE ANSIEDAD | C37: 3
A38: DEMENCIAS (INCLUYE ALZHEIMER) | B38: LEVE
B39: MODERADO
B40: AVANZADO
A41: ESQUIZOFRENIA
A42: TRASTORNO ADAPTATIVO | C42: 4
A43: TRASTORNOS DE LA CONDUCTA ALIMENTARIA
...

Sheet CALCULO
A1: NEGATIVO HAY QUE EGRESAR, POSITIVO HAY QUE INGRESAR | C1: T O T A L | D1: Columna1 | E1: Columna2 | F1: GRUPO DE EDAD (en años) | G1: Columna3 | H1: Columna4 | I1: Columna5 | J1: Columna6 | K1: Columna7 | L1: Columna8 | M1: Columna9 | N1: Columna10 | O1: Columna11 | P1: Columna12 | Q1: Columna13 | R1: Columna14 | S1: Columna15 | T1: Columna16 | U1: Columna17 | V1: Columna18 | W1: Columna19 | X1: Columna20 | Y1: Columna21 | Z1: Columna22 | AA1: Columna23 | AB1: Columna24 | AC1: Columna25 | AD1: Columna26 | AE1: Columna27 | AF1: Columna28 | AG1: Columna29 | AH1: Columna30 | AI1: Columna31 | AJ1: Columna32 | AK1: Columna33 | AL1: Columna34 | AM1: Columna35 | AN1: Gestantes | AO1: Madre de Hijo menor de 5 años | AP1: Pueblos Originarios | AQ1: Columna36 | AR1: Migrantes | AS1: Columna37 | AT1: Niños, Niñas, Adolescentes y Jóvenes SENAME | AU1: Niños, Niñas, Adolescentes y Jóvenes Mejor Niñez | AV1: Plan Cuidado Integral Elaborado | AW1: TRANS | AX1: Columna38
F2: 0 a 4 años | H2: 5 a 9 años | J2: 10 a 14 años | L2: 15 a 19 años | N2: 20 a 24 años | P2: 25 a 29 años | R2: 30 a 34 años | T2: 35 a 39 años | V2: 40 a 44 años | X2: 45 a 49 años | Z2: 50 a 54 años | AB2: 55 a 59 años | AD2: 60 a 64 años | AF2: 65 a 69 años | AH2: 70 a 74 años | AJ2: 75 a 79 años | AL2: 80 y más años
C3: Ambos sexos | D3: Hombres | E3: Mujeres | F3: Hombres | G3: Mujeres | H3: Hombres | I3: Mujeres | J3: Hombres | K3: Mujeres | L3: Hombres | M3: Mujeres | N3: Hombres | O3: Mujeres | P3: Hombres | Q3: Mujeres | R3: Hombres | S3: Mujeres | T3: Hombres | U3: Mujeres | V3: Hombres | W3: Mujeres | X3: Hombres | Y3: Mujeres | Z3: Hombres | AA3: Mujeres | AB3: Hombres | AC3: Mujeres | AD3: Hombres | AE3: Mujeres | AF3: Hombres | AG3: Mujeres | AH3: Hombres | AI3: Mujeres | AJ3: Hombres | AK3: Mujeres | AL3: Hombres | AM3: Mujeres | AP3: Hombres | AQ3: Mujeres | AR3: Hombres | AS3: Mujeres | AW3: Masculino | AX3: Femenino
A4: NUMERO DE PERSONAS EN CONTROL EN EL PROGRAMA | C4: =+NUEVO!C4-ANTIGUO!C4 -> -15 | D4: =+NUEVO!D4-ANTIGUO!D4 -> -27 | E4: =+NUEVO!E4-ANTIGUO!E4 -> 12 | F4: =+NUEVO!F4-ANTIGUO!F4 -> 0 | G4: =+NUEVO!G4-ANTIGUO!G4 -> 0 | H4: =+NUEVO!H4-ANTIGUO!H4 -> 0 | I4: =+NUEVO!I4-ANTIGUO!I4 -> -1 | J4: =+NUEVO!J4-ANTIGUO!J4 -> -4 | ... AX4: =+NUEVO!AX4-ANTIGUO!AX4 -> -3
A5: FACTORES DE RIESGO Y CONDICIONANTES DE LA SALUD MENTAL
A6: VIOLENCIA | B6: VICTIMA | C6: =+NUEVO!C6-ANTIGUO!C6 -> 0 | D6: =+NUEVO!D6-ANTIGUO!D6 -> 0 | E6: =+NUEVO!E6-ANTIGUO!E6 -> 0 | F6: =+NUEVO!F6-ANTIGUO!F6 -> 0 | G6: =+NUEVO!G6-ANTIGUO!G6 -> 0 | H6: =+NUEVO!H6-ANTIGUO!H6 -> 0 | I6: =+NUEVO!I6-ANTIGUO!I6 -> 0 | J6: =+NUEVO!J6-ANTIGUO!J6 -> 0 | ... AX6: =+NUEVO!AX6-ANTIGUO!AX6 -> 0
B7: AGRESOR/A | C7: =+NUEVO!C7-ANTIGUO!C7 -> 0 | D7: =+NUEVO!D7-ANTIGUO!D7 -> 0 | E7: =+NUEVO!E7-ANTIGUO!E7 -> 0 | F7: =+NUEVO!F7-ANTIGUO!F7 -> 0 | G7: =+NUEVO!G7-ANTIGUO!G7 -> 0 | H7: =+NUEVO!H7-ANTIGUO!H7 -> 0 | I7: =+NUEVO!I7-ANTIGUO!I7 -> 0 | J7: =+NUEVO!J7-ANTIGUO!J7 -> 0 | ... AX7: =+NUEVO!AX7-ANTIGUO!AX7 -> 0
C8: =+NUEVO!C8-ANTIGUO!C8 -> 0 | D8: =+NUEVO!D8-ANTIGUO!D8 -> 0 | E8: =+NUEVO!E8-ANTIGUO!E8 -> 0 | F8: =+NUEVO!F8-ANTIGUO!F8 -> 0 | G8: =+NUEVO!G8-ANTIGUO!G8 -> 0 | H8: =+NUEVO!H8-ANTIGUO!H8 -> 0 | I8: =+NUEVO!I8-ANTIGUO!I8 -> 0 | J8: =+NUEVO!J8-ANTIGUO!J8 -> 0 | ... AX8: =+NUEVO!AX8-ANTIGUO!AX8 -> 0
C9: =+NUEVO!C9-ANTIGUO!C9 -> 0 | D9: =+NUEVO!D9-ANTIGUO!D9 -> 0 | E9: =+NUEVO!E9-ANTIGUO!E9 -> 0 | F9: =+NUEVO!F9-ANTIGUO!F9 -> 0 | G9: =+NUEVO!G9-ANTIGUO!G9 -> 0 | H9: =+NUEVO!H9-ANTIGUO!H9 -> 0 | I9: =+NUEVO!I9-ANTIGUO!I9 -> 0 | J9: =+NUEVO!J9-ANTIGUO!J9 -> 0 | ... AX9: =+NUEVO!AX9-ANTIGUO!AX9 -> 0
C10: =+NUEVO!C10-ANTIGUO!C10 -> 0 | D10: =+NUEVO!D10-ANTIGUO!D10 -> 0 | E10: =+NUEVO!E10-ANTIGUO!E10 -> 0 | F10: =+NUEVO!F10-ANTIGUO!F10 -> 0 | G10: =+NUEVO!G10-ANTIGUO!G10 -> 0 | H10: =+NUEVO!H10-ANTIGUO!H10 -> 0 | I10: =+NUEVO!I10-ANTIGUO!I10 -> 0 | J10: =+NUEVO!J10-ANTIGUO!J10 -> 0 | ... AX10: =+NUEVO!AX10-ANTIGUO!AX10 -> 0
C11: =+NUEVO!C11-ANTIGUO!C11 -> 0 | D11: =+NUEVO!D11-ANTIGUO!D11 -> 0 | E11: =+NUEVO!E11-ANTIGUO!E11 -> 0 | F11: =+NUEVO!F11-ANTIGUO!F11 -> 0 | G11: =+NUEVO!G11-ANTIGUO!G11 -> 0 | H11: =+NUEVO!H11-ANTIGUO!H11 -> 0 | I11: =+NUEVO!I11-ANTIGUO!I11 -> 0 | J11: =+NUEVO!J11-ANTIGUO!J11 -> 0 | ... AX11: =+NUEVO!AX11-ANTIGUO!AX11 -> 0
A12: ABUSO SEXUAL | C12: =+NUEVO!C12-ANTIGUO!C12 -> 0 | D12: =+NUEVO!D12-ANTIGUO!D12 -> 0 | E12: =+NUEVO!E12-ANTIGUO!E12 -> 0 | F12: =+NUEVO!F12-ANTIGUO!F12 -> 0 | G12: =+NUEVO!G12-ANTIGUO!G12 -> 0 | H12: =+NUEVO!H12-ANTIGUO!H12 -> 0 | I12: =+NUEVO!I12-ANTIGUO!I12 -> 0 | J12: =+NUEVO!J12-ANTIGUO!J12 -> 0 | ... AX12: =+NUEVO!AX12-ANTIGUO!AX12 -> 0
A13: SUICIDIO | B13: IDEACIÓN | C13: =+NUEVO!C13-ANTIGUO!C13 -> -2 | D13: =+NUEVO!D13-ANTIGUO!D13 -> -1 | E13: =+NUEVO!E13-ANTIGUO!E13 -> -1 | F13: =+NUEVO!F13-ANTIGUO!F13 -> 0 | G13: =+NUEVO!G13-ANTIGUO!G13 -> 0 | H13: =+NUEVO!H13-ANTIGUO!H13 -> 0 | I13: =+NUEVO!I13-ANTIGUO!I13 -> 0 | J13: =+NUEVO!J13-ANTIGUO!J13 -> 0 | ... AX13: =+NUEVO!AX13-ANTIGUO!AX13 -> 0
B14: INTENTO | C14: =+NUEVO!C14-ANTIGUO!C14 -> 1 | D14: =+NUEVO!D14-ANTIGUO!D14 -> -1 | E14: =+NUEVO!E14-ANTIGUO!E14 -> 2 | F14: =+NUEVO!F14-ANTIGUO!F14 -> 0 | G14: =+NUEVO!G14-ANTIGUO!G14 -> 0 | H14: =+NUEVO!H14-ANTIGUO!H14 -> 0 | I14: =+NUEVO!I14-ANTIGUO!I14 -> 0 | J14: =+NUEVO!J14-ANTIGUO!J14 -> 0 | ... AX14: =+NUEVO!AX14-ANTIGUO!AX14 -> 0
A15: PERSONAS CON DIAGNOSTICOS DE TRASTORNOS MENTALES | C15: =+NUEVO!C15-ANTIGUO!C15 -> 10 | D15: =+NUEVO!D15-ANTIGUO!D15 -> -19 | E15: =+NUEVO!E15-ANTIGUO!E15 -> 29 | F15: =+NUEVO!F15-ANTIGUO!F15 -> 0 | G15: =+NUEVO!G15-ANTIGUO!G15 -> 0 | H15: =+NUEVO!H15-ANTIGUO!H15 -> 0 | I15: =+NUEVO!I15-ANTIGUO!I15 -> -1 | J15: =+NUEVO!J15-ANTIGUO!J15 -> -4 | ... AX15: =+NUEVO!AX15-ANTIGUO!AX15 -> -2
A16: TRASTORNOS DEL HUMOR (AFECTIVOS) | B16: DEPRESIÓN LEVE | C16: =+NUEVO!C16-ANTIGUO!C16 -> 4 | D16: =+NUEVO!D16-ANTIGUO!D16 -> 1 | E16: =+NUEVO!E16-ANTIGUO!E16 -> 3 | F16: =+NUEVO!F16-ANTIGUO!F16 -> 0 | G16: =+NUEVO!G16-ANTIGUO!G16 -> 0 | H16: =+NUEVO!H16-ANTIGUO!H16 -> 0 | I16: =+NUEVO!I16-ANTIGUO!I16 -> 0 | J16: =+NUEVO!J16-ANTIGUO!J16 -> 0 | ... AX16: =+NUEVO!AX16-ANTIGUO!AX16 -> 0
B17: DEPRESIÓN MODERADA | C17: =+NUEVO!C17-ANTIGUO!C17 -> 20 | D17: =+NUEVO!D17-ANTIGUO!D17 -> 3 | E17: =+NUEVO!E17-ANTIGUO!E17 -> 17 | F17: =+NUEVO!F17-ANTIGUO!F17 -> 0 | G17: =+NUEVO!G17-ANTIGUO!G17 -> 0 | H17: =+NUEVO!H17-ANTIGUO!H17 -> 0 | I17: =+NUEVO!I17-ANTIGUO!I17 -> 0 | J17: =+NUEVO!J17-ANTIGUO!J17 -> 0 | ... AX17: =+NUEVO!AX17-ANTIGUO!AX17 -> 0
B18: DEPRESIÓN GRAVE | C18: =+NUEVO!C18-ANTIGUO!C18 -> 5 | D18: =+NUEVO!D18-ANTIGUO!D18 -> 0 | E18: =+NUEVO!E18-ANTIGUO!E18 -> 5 | F18: =+NUEVO!F18-ANTIGUO!F18 -> 0 | G18: =+NUEVO!G18-ANTIGUO!G18 -> 0 | H18: =+NUEVO!H18-ANTIGUO!H18 -> 0 | I18: =+NUEVO!I18-ANTIGUO!I18 -> 0 | J18: =+NUEVO!J18-ANTIGUO!J18 -> 0 | ... AX18: =+NUEVO!AX18-ANTIGUO!AX18 -> 0
B19: DEPRESIÓN POST PARTO | C19: =+NUEVO!C19-ANTIGUO!C19 -> 0 | D19: =+NUEVO!D19-ANTIGUO!D19 -> 0 | E19: =+NUEVO!E19-ANTIGUO!E19 -> 0 | F19: =+NUEVO!F19-ANTIGUO!F19 -> 0 | G19: =+NUEVO!G19-ANTIGUO!G19 -> 0 | H19: =+NUEVO!H19-ANTIGUO!H19 -> 0 | I19: =+NUEVO!I19-ANTIGUO!I19 -> 0 | J19: =+NUEVO!J19-ANTIGUO!J19 -> 0 | ... AX19: =+NUEVO!AX19-ANTIGUO!AX19 -> 0
B20: TRASTORNO BIPOLAR | C20: =+NUEVO!C20-ANTIGUO!C20 -> 3 | D20: =+NUEVO!D20-ANTIGUO!D20 -> 1 | E20: =+NUEVO!E20-ANTIGUO!E20 -> 2 | F20: =+NUEVO!F20-ANTIGUO!F20 -> 0 | G20: =+NUEVO!G20-ANTIGUO!G20 -> 0 | H20: =+NUEVO!H20-ANTIGUO!H20 -> 0 | I20: =+NUEVO!I20-ANTIGUO!I20 -> 0 | J20: =+NUEVO!J20-ANTIGUO!J20 -> 0 | ... AX20: =+NUEVO!AX20-ANTIGUO!AX20 -> 0
A21: TRASTORNOS MENTALES Y DEL COMPORTAMIENTO DEBIDO A CONSUMO SUSTANCIAS PSICOTROPICAS | B21: CONSUMO PERJUDICIAL DE ALCOHOL | C21: =+NUEVO!C21-ANTIGUO!C21 -> 0 | D21: =+NUEVO!D21-ANTIGUO!D21 -> 0 | E21: =+NUEVO!E21-ANTIGUO!E21 -> 0 | F21: =+NUEVO!F21-ANTIGUO!F21 -> 0 | G21: =+NUEVO!G21-ANTIGUO!G21 -> 0 | H21: =+NUEVO!H21-ANTIGUO!H21 -> 0 | I21: =+NUEVO!I21-ANTIGUO!I21 -> 0 | J21: =+NUEVO!J21-ANTIGUO!J21 -> 0 | ... AX21: =+NUEVO!AX21-ANTIGUO!AX21 -> 0
B22: CONSUMO DEPENDIENTE DEL ALCOHOL | C22: =+NUEVO!C22-ANTIGUO!C22 -> 1 | D22: =+NUEVO!D22-ANTIGUO!D22 -> 2 | E22: =+NUEVO!E22-ANTIGUO!E22 -> -1 | F22: =+NUEVO!F22-ANTIGUO!F22 -> 0 | G22: =+NUEVO!G22-ANTIGUO!G22 -> 0 | H22: =+NUEVO!H22-ANTIGUO!H22 -> 0 | I22: =+NUEVO!I22-ANTIGUO!I22 -> 0 | J22: =+NUEVO!J22-ANTIGUO!J22 -> 0 | ... AX22: =+NUEVO!AX22-ANTIGUO!AX22 -> 0
B23: CONSUMO PERJUDICIAL DE DROGAS | C23: =+NUEVO!C23-ANTIGUO!C23 -> 3 | D23: =+NUEVO!D23-ANTIGUO!D23 -> 3 | E23: =+NUEVO!E23-ANTIGUO!E23 -> 0 | F23: =+NUEVO!F23-ANTIGUO!F23 -> 0 | G23: =+NUEVO!G23-ANTIGUO!G23 -> 0 | H23: =+NUEVO!H23-ANTIGUO!H23 -> 0 | I23: =+NUEVO!I23-ANTIGUO!I23 -> 0 | J23: =+NUEVO!J23-ANTIGUO!J23 -> 0 | ... AX23: =+NUEVO!AX23-ANTIGUO!AX23 -> 0
B24: CONSUMO DEPENDIENTE DE DROGAS | C24: =+NUEVO!C24-ANTIGUO!C24 -> 2 | D24: =+NUEVO!D24-ANTIGUO!D24 -> 1 | E24: =+NUEVO!E24-ANTIGUO!E24 -> 1 | F24: =+NUEVO!F24-ANTIGUO!F24 -> 0 | G24: =+NUEVO!G24-ANTIGUO!G24 -> 0 | H24: =+NUEVO!H24-ANTIGUO!H24 -> 0 | I24: =+NUEVO!I24-ANTIGUO!I24 -> 0 | J24: =+NUEVO!J24-ANTIGUO!J24 -> 0 | ... AX24: =+NUEVO!AX24-ANTIGUO!AX24 -> 0
B25: CONSUMO DE DROGAS Y ALCOHOL | C25: =+NUEVO!C25-ANTIGUO!C25 -> -1 | D25: =+NUEVO!D25-ANTIGUO!D25 -> -1 | E25: =+NUEVO!E25-ANTIGUO!E25 -> 0 | F25: =+NUEVO!F25-ANTIGUO!F25 -> 0 | G25: =+NUEVO!G25-ANTIGUO!G25 -> 0 | H25: =+NUEVO!H25-ANTIGUO!H25 -> 0 | I25: =+NUEVO!I25-ANTIGUO!I25 -> 0 | J25: =+NUEVO!J25-ANTIGUO!J25 -> 0 | ... AX25: =+NUEVO!AX25-ANTIGUO!AX25 -> 0
A26: TRASTORNOS DEL COMPORTAMIENTO Y DE LAS EMOCIONES DE COMIENZO HABITUAL EN LA INFANCIA Y ADOLESCENCIA | B26: TRASTORNO HIPERCINÉTICO | C26: =+NUEVO!C26-ANTIGUO!C26 -> 7 | D26: =+NUEVO!D26-ANTIGUO!D26 -> 3 | E26: =+NUEVO!E26-ANTIGUO!E26 -> 4 | F26: =+NUEVO!F26-ANTIGUO!F26 -> 0 | G26: =+NUEVO!G26-ANTIGUO!G26 -> 0 | H26: =+NUEVO!H26-ANTIGUO!H26 -> 2 | I26: =+NUEVO!I26-ANTIGUO!I26 -> 0 | J26: =+NUEVO!J26-ANTIGUO!J26 -> 0 | ... AX26: =+NUEVO!AX26-ANTIGUO!AX26 -> 0
B27: TRASTORNO DISOCIAL DESAFIANTE Y OPOSICIONISTA | C27: =+NUEVO!C27-ANTIGUO!C27 -> 1 | D27: =+NUEVO!D27-ANTIGUO!D27 -> 0 | E27: =+NUEVO!E27-ANTIGUO!E27 -> 1 | F27: =+NUEVO!F27-ANTIGUO!F27 -> 0 | G27: =+NUEVO!G27-ANTIGUO!G27 -> 0 | H27: =+NUEVO!H27-ANTIGUO!H27 -> 0 | I27: =+NUEVO!I27-ANTIGUO!I27 -> 0 | J27: =+NUEVO!J27-ANTIGUO!J27 -> 0 | ... AX27: =+NUEVO!AX27-ANTIGUO!AX27 -> 0
B28: TRASTORNO DE ANSIEDAD DE SEPARACIÓN EN LA INFANCIA | C28: =+NUEVO!C28-ANTIGUO!C28 -> 0 | D28: =+NUEVO!D28-ANTIGUO!D28 -> 0 | E28: =+NUEVO!E28-ANTIGUO!E28 -> 0 | F28: =+NUEVO!F28-ANTIGUO!F28 -> 0 | G28: =+NUEVO!G28-ANTIGUO!G28 -> 0 | H28: =+NUEVO!H28-ANTIGUO!H28 -> 0 | I28: =+NUEVO!I28-ANTIGUO!I28 -> 0 | J28: =+NUEVO!J28-ANTIGUO!J28 -> 0 | ... AX28: =+NUEVO!AX28-ANTIGUO!AX28 -> 0
B29: OTROS TRASTORNOS DEL COMPORTAMIENTO Y DE LAS EMOCIONES DE COMIENZO HABITUAL EN LA INFANCIA Y ADOLESCENCIA | C29: =+NUEVO!C29-ANTIGUO!C29 -> 1 | D29: =+NUEVO!D29-ANTIGUO!D29 -> -1 | E29: =+NUEVO!E29-ANTIGUO!E29 -> 2 | F29: =+NUEVO!F29-ANTIGUO!F29 -> 0 | G29: =+NUEVO!G29-ANTIGUO!G29 -> 0 | H29: =+NUEVO!H29-ANTIGUO!H29 -> 0 | I29: =+NUEVO!I29-ANTIGUO!I29 -> 0 | J29: =+NUEVO!J29-ANTIGUO!J29 -> 0 | ... AX29: =+NUEVO!AX29-ANTIGUO!AX29 -> 0
A30: TRASTORNOS DE ANSIEDAD | B30: TRASTORNO DE ESTRÉS POST TRAUMATICO | C30: =+NUEVO!C30-ANTIGUO!C30 -> 1 | D30: =+NUEVO!D30-ANTIGUO!D30 -> 1 | E30: =+NUEVO!E30-ANTIGUO!E30 -> 0 | F30: =+NUEVO!F30-ANTIGUO!F30 -> 0 | G30: =+NUEVO!G30-ANTIGUO!G30 -> 0 | H30: =+NUEVO!H30-ANTIGUO!H30 -> 0 | I30: =+NUEVO!I30-ANTIGUO!I30 -> 0 | J30: =+NUEVO!J30-ANTIGUO!J30 -> 1 | ... AX30: =+NUEVO!AX30-ANTIGUO!AX30 -> 0
B31: TRASTORNO DE PÁNICO | C31: =+NUEVO!C31-ANTIGUO!C31 -> 4 | D31: =+NUEVO!D31-ANTIGUO!D31 -> 1 | E31: =+NUEVO!E31-ANTIGUO!E31 -> 3 | F31: =+NUEVO!F31-ANTIGUO!F31 -> 0 | G31: =+NUEVO!G31-ANTIGUO!G31 -> 0 | H31: =+NUEVO!H31-ANTIGUO!H31 -> 0 | I31: =+NUEVO!I31-ANTIGUO!I31 -> 0 | J31: =+NUEVO!J31-ANTIGUO!J31 -> 1 | ... AX31: =+NUEVO!AX31-ANTIGUO!AX31 -> 0
B32: FOBIAS SOCIALES | C32: =+NUEVO!C32-ANTIGUO!C32 -> 0 | D32: =+NUEVO!D32-ANTIGUO!D32 -> 0 | E32: =+NUEVO!E32-ANTIGUO!E32 -> 0 | F32: =+NUEVO!F32-ANTIGUO!F32 -> 0 | G32: =+NUEVO!G32-ANTIGUO!G32 -> 0 | H32: =+NUEVO!H32-ANTIGUO!H32 -> 0 | I32: =+NUEVO!I32-ANTIGUO!I32 -> 0 | J32: =+NUEVO!J32-ANTIGUO!J32 -> 0 | ... AX32: =+NUEVO!AX32-ANTIGUO!AX32 -> 1
B33: TRASTORNOS DE ANSIEDAD GENERALIZADA | C33: =+NUEVO!C33-ANTIGUO!C33 -> -1 | D33: =+NUEVO!D33-ANTIGUO!D33 -> -1 | E33: =+NUEVO!E33-ANTIGUO!E33 -> 0 | F33: =+NUEVO!F33-ANTIGUO!F33 -> 0 | G33: =+NUEVO!G33-ANTIGUO!G33 -> 0 | H33: =+NUEVO!H33-ANTIGUO!H33 -> 0 | I33: =+NUEVO!I33-ANTIGUO!I33 -> 0 | J33: =+NUEVO!J33-ANTIGUO!J33 -> 0 | ... AX33: =+NUEVO!AX33-ANTIGUO!AX33 -> 0
B34: OTROS TRASTORNOS DE ANSIEDAD | C34: =+NUEVO!C34-ANTIGUO!C34 -> 315 | D34: =+NUEVO!D34-ANTIGUO!D34 -> 61 | E34: =+NUEVO!E34-ANTIGUO!E34 -> 254 | F34: =+NUEVO!F34-ANTIGUO!F34 -> 0 | G34: =+NUEVO!G34-ANTIGUO!G34 -> 0 | H34: =+NUEVO!H34-ANTIGUO!H34 -> 0 | I34: =+NUEVO!I34-ANTIGUO!I34 -> 0 | J34: =+NUEVO!J34-ANTIGUO!J34 -> 1 | ... AX34: =+NUEVO!AX34-ANTIGUO!AX34 -> 0
A35: DEMENCIAS (INCLUYE ALZHEIMER) | B35: LEVE | C35: =+NUEVO!C35-ANTIGUO!C35 -> 0 | D35: =+NUEVO!D35-ANTIGUO!D35 -> 0 | E35: =+NUEVO!E35-ANTIGUO!E35 -> 0 | F35: =+NUEVO!F35-ANTIGUO!F35 -> 0 | G35: =+NUEVO!G35-ANTIGUO!G35 -> 0 | H35: =+NUEVO!H35-ANTIGUO!H35 -> 0 | I35: =+NUEVO!I35-ANTIGUO!I35 -> 0 | J35: =+NUEVO!J35-ANTIGUO!J35 -> 0 | ... AX35: =+NUEVO!AX35-ANTIGUO!AX35 -> 0
B36: MODERADO | C36: =+NUEVO!C36-ANTIGUO!C36 -> 0 | D36: =+NUEVO!D36-ANTIGUO!D36 -> 2 | E36: =+NUEVO!E36-ANTIGUO!E36 -> -2 | F36: =+NUEVO!F36-ANTIGUO!F36 -> 0 | G36: =+NUEVO!G36-ANTIGUO!G36 -> 0 | H36: =+NUEVO!H36-ANTIGUO!H36 -> 0 | I36: =+NUEVO!I36-ANTIGUO!I36 -> 0 | J36: =+NUEVO!J36-ANTIGUO!J36 -> 0 | ... AX36: =+NUEVO!AX36-ANTIGUO!AX36 -> 0
B37: AVANZADO | C37: =+NUEVO!C37-ANTIGUO!C37 -> 0 | D37: =+NUEVO!D37-ANTIGUO!D37 -> 0 | E37: =+NUEVO!E37-ANTIGUO!E37 -> 0 | F37: =+NUEVO!F37-ANTIGUO!F37 -> 0 | G37: =+NUEVO!G37-ANTIGUO!G37 -> 0 | H37: =+NUEVO!H37-ANTIGUO!H37 -> 0 | I37: =+NUEVO!I37-ANTIGUO!I37 -> 0 | J37: =+NUEVO!J37-ANTIGUO!J37 -> 0 | ... AX37: =+NUEVO!AX37-ANTIGUO!AX37 -> 0
A38: ESQUIZOFRENIA | C38: =+NUEVO!C38-ANTIGUO!C38 -> 0 | D38: =+NUEVO!D38-ANTIGUO!D38 -> 0 | E38: =+NUEVO!E38-ANTIGUO!E38 -> 0 | F38: =+NUEVO!F38-ANTIGUO!F38 -> 0 | G38: =+NUEVO!G38-ANTIGUO!G38 -> 0 | H38: =+NUEVO!H38-ANTIGUO!H38 -> 0 | I38: =+NUEVO!I38-ANTIGUO!I38 -> 0 | J38: =+NUEVO!J38-ANTIGUO!J38 -> 0 | ... AX38: =+NUEVO!AX38-ANTIGUO!AX38 -> 0
A39: TRASTORNO ADAPTATIVO | C39: =+NUEVO!C39-ANTIGUO!C39 -> 125 | D39: =+NUEVO!D39-ANTIGUO!D39 -> 24 | E39: =+NUEVO!E39-ANTIGUO!E39 -> 101 | F39: =+NUEVO!F39-ANTIGUO!F39 -> 0 | G39: =+NUEVO!G39-ANTIGUO!G39 -> 0 | H39: =+NUEVO!H39-ANTIGUO!H39 -> 0 | I39: =+NUEVO!I39-ANTIGUO!I39 -> 0 | J39: =+NUEVO!J39-ANTIGUO!J39 -> 3 | ... AX39: =+NUEVO!AX39-ANTIGUO!AX39 -> -1
A40: TRASTORNOS DE LA CONDUCTA ALIMENTARIA | C40: =+NUEVO!C40-ANTIGUO!C40 -> 1 | D40: =+NUEVO!D40-ANTIGUO!D40 -> 0 | E40: =+NUEVO!E40-ANTIGUO!E40 -> 1 | F40: =+NUEVO!F40-ANTIGUO!F40 -> 0 | G40: =+NUEVO!G40-ANTIGUO!G40 -> 0 | H40: =+NUEVO!H40-ANTIGUO!H40 -> 0 | I40: =+NUEVO!I40-ANTIGUO!I40 -> 0 | J40: =+NUEVO!J40-ANTIGUO!J40 -> 0 | ... AX40: =+NUEVO!AX40-ANTIGUO!AX40 -> 0
...

Sheet INGRESOS
A1: CONCEPTO | C1: T O T A L | F1: GRUPO DE EDAD (en años) | AN1: Gestantes | AO1: Madre de Hijo menor de 5 años | AP1: Pueblos Originarios | AZ1: ACCESORIAS | BA1: Migrantes | BC1: Niños, Niñas, Adolescentes y Jóvenes SENAME | BD1: Niños, Niñas, Adolescentes y Jóvenes Mejor Niñez | BE1: Plan Cuidado Integral Elaborado | BF1: TRANS
F2: 0 a 4 años | H2: 5 a 9 años | J2: 10 a 14 años | L2: 15 a 19 años | N2: 20 a 24 años | P2: 25 a 29 años | R2: 30 a 34 años | T2: 35 a 39 años | V2: 40 a 44 años | X2: 45 a 49 años | Z2: 50 a 54 años | AB2: 55 a 59 años | AD2: 60 a 64 años | AF2: 65 a 69 años | AH2: 70 a 74 años | AJ2: 75 a 79 años | AL2: 80 y más años | AR2: Niños, Niñas, Adolescentes y Jóvenes SENAME | AS2: Niños, Niñas, Adolescentes y Jóvenes Mejor Niñez | AT2: Migrantes | AV2: TRANS | AW2: TRANS Femenino/ Masculino
C3: Ambos sexos | D3: Hombres | E3: Mujeres | F3: Hombres2 | G3: Mujeres3 | H3: Hombres4 | I3: Mujeres5 | J3: Hombres6 | K3: Mujeres7 | L3: Hombres8 | M3: Mujeres9 | N3: Hombres10 | O3: Mujeres11 | P3: Hombres12 | Q3: Mujeres13 | R3: Hombres14 | S3: Mujeres15 | T3: Hombres16 | U3: Mujeres17 | V3: Hombres18 | W3: Mujeres19 | X3: Hombres20 | Y3: Mujeres21 | Z3: Hombres22 | AA3: Mujeres23 | AB3: Hombres24 | AC3: Mujeres25 | AD3: Hombres26 | AE3: Mujeres27 | AF3: Hombres | AG3: Mujeres28 | AH3: Hombres 29 | AI3: Mujeres30 | AJ3: Hombres 31 | AK3: Mujeres32 | AL3: Hombres33 | AM3: Mujeres34 | AP3: Hombres | AQ3: Mujeres | AT3: Hombres | AU3: Mujeres | AV3: Masculino | AW3: Femenino | BA3: Hombres | BB3: Mujeres | BF3: Masculino | BG3: Femenino
A4: NUMERO DE PERSONAS EN CONTROL EN EL PROGRAMA | C4: =+SUM(F4:AM4) -> 68 | D4: =+IF(AND(CALCULO!D4<>"", CALCULO!D4>0), CALCULO!D4, "") | F4: =+IF(AND(CALCULO!F4<>"", CALCULO!F4>0), CALCULO!F4, 0) -> 0 | G4: =+IF(AND(CALCULO!G4<>"", CALCULO!G4>0), CALCULO!G4, 0) -> 0 | H4: =+IF(AND(CALCULO!H4<>"", CALCULO!H4>0), CALCULO!H4, 0) -> 0 | I4: =+IF(AND(CALCULO!I4<>"", CALCULO!I4>0), CALCULO!I4, 0) -> 0 | J4: =+IF(AND(CALCULO!J4<>"", CALCULO!J4>0), CALCULO!J4, 0) -> 0 | K4: =+IF(AND(CALCULO!K4<>"",CALCULO!K4>0),CALCULO!K4,0) -> 0 | L4: =+IF(AND(CALCULO!L4<>"", CALCULO!L4>0), CALCULO!L4, 0) -> 0 | M4: =+IF(AND(CALCULO!M4<>"", CALCULO!M4>0), CALCULO!M4, 0) -> 11 | N4: =+IF(AND(CALCULO!N4<>"", CALCULO!N4>0), CALCULO!N4, 0) -> 0 | O4: =+IF(AND(CALCULO!O4<>"", CALCULO!O4>0), CALCULO!O4, 0) -> 0 | P4: =+IF(AND(CALCULO!P4<>"", CALCULO!P4>0), CALCULO!P4, 0) -> 0 | Q4: =+IF(AND(CALCULO!Q4<>"", CALCULO!Q4>0), CALCULO!Q4, 0) -> 6 | R4: =+IF(AND(CALCULO!R4<>"", CALCULO!R4>0), CALCULO!R4, 0) -> 0 | S4: =+IF(AND(CALCULO!S4<>"", CALCULO!S4>0), CALCULO!S4, 0) -> 0 | ... AW4: =+IF(AND(CALCULO!AW4<>"", CALCULO!AW4>0), CALCULO!AW4, 0) -> 0 | BE4: =+IF(AND(CALCULO!AV4<>"", CALCULO!AV4>0), CALCULO!AV4, "")
A5: FACTORES DE RIESGO Y CONDICIONANTES DE LA SALUD MENTAL | C5: =+SUM(F5:AM5) -> 0 | E5: =+IF(AND(CALCULO!E5<>"", CALCULO!E5>0), CALCULO!E5, "") | F5: =+IF(AND(CALCULO!F5<>"", CALCULO!F5>0), CALCULO!F5, 0) -> 0 | G5: =+IF(AND(CALCULO!G5<>"", CALCULO!G5>0), CALCULO!G5, 0) -> 0 | H5: =+IF(AND(CALCULO!H5<>"", CALCULO!H5>0), CALCULO!H5, 0) -> 0 | I5: =+IF(AND(CALCULO!I5<>"", CALCULO!I5>0), CALCULO!I5, 0) -> 0 | J5: =+IF(AND(CALCULO!J5<>"", CALCULO!J5>0), CALCULO!J5, 0) -> 0 | K5: =+IF(AND(CALCULO!K5<>"",CALCULO!K5>0),CALCULO!K5,0) -> 0 | L5: =+IF(AND(CALCULO!L5<>"", CALCULO!L5>0), CALCULO!L5, 0) -> 0 | M5: =+IF(AND(CALCULO!M5<>"", CALCULO!M5>0), CALCULO!M5, 0) -> 0 | N5: =+IF(AND(CALCULO!N5<>"", CALCULO!N5>0), CALCULO!N5, 0) -> 0 | O5: =+IF(AND(CALCULO!O5<>"", CALCULO!O5>0), CALCULO!O5, 0) -> 0 | P5: =+IF(AND(CALCULO!P5<>"", CALCULO!P5>0), CALCULO!P5, 0) -> 0 | Q5: =+IF(AND(CALCULO!Q5<>"", CALCULO!Q5>0), CALCULO!Q5, 0) -> 0 | R5: =+IF(AND(CALCULO!R5<>"", CALCULO!R5>0), CALCULO!R5, 0) -> 0 | S5: =+IF(AND(CALCULO!S5<>"", CALCULO!S5>0), CALCULO!S5, 0) -> 0 | ... AW5: =+IF(AND(CALCULO!AW5<>"", CALCULO!AW5>0), CALCULO!AW5, 0) -> 0 | BE5: =+IF(AND(CALCULO!AV5<>"", CALCULO!AV5>0), CALCULO!AV5, "")
A6: VIOLENCIA | B6: VICTIMA | C6: =+SUM(F6:AM6) -> 0 | E6: =+IF(AND(CALCULO!E6<>"", CALCULO!E6>0), CALCULO!E6, "") | F6: =+IF(AND(CALCULO!F6<>"", CALCULO!F6>0), CALCULO!F6, 0) -> 0 | G6: =+IF(AND(CALCULO!G6<>"", CALCULO!G6>0), CALCULO!G6, 0) -> 0 | H6: =+IF(AND(CALCULO!H6<>"", CALCULO!H6>0), CALCULO!H6, 0) -> 0 | I6: =+IF(AND(CALCULO!I6<>"", CALCULO!I6>0), CALCULO!I6, 0) -> 0 | J6: =+IF(AND(CALCULO!J6<>"", CALCULO!J6>0), CALCULO!J6, 0) -> 0 | K6: =+IF(AND(CALCULO!K6<>"", CALCULO!K6>0), CALCULO!K6, 0) -> 0 | L6: =+IF(AND(CALCULO!L6<>"", CALCULO!L6>0), CALCULO!L6, 0) -> 0 | M6: =+IF(AND(CALCULO!M6<>"", CALCULO!M6>0), CALCULO!M6, 0) -> 0 | ... AW6: =+IF(AND(CALCULO!AW6<>"", CALCULO!AW6>0), CALCULO!AW6, 0) -> 0 | BE6: =+IF(AND(CALCULO!AV6<>"", CALCULO!AV6>0), CALCULO!AV6, "0") -> 0
B7: AGRESOR/A | C7: =+SUM(F7:AM7) -> 0 | E7: =+IF(AND(CALCULO!E7<>"", CALCULO!E7>0), CALCULO!E7, "") | F7: =+IF(AND(CALCULO!F7<>"", CALCULO!F7>0), CALCULO!F7, 0) -> 0 | G7: =+IF(AND(CALCULO!G7<>"", CALCULO!G7>0), CALCULO!G7, 0) -> 0 | H7: =+IF(AND(CALCULO!H7<>"", CALCULO!H7>0), CALCULO!H7, 0) -> 0 | I7: =+IF(AND(CALCULO!I7<>"", CALCULO!I7>0), CALCULO!I7, 0) -> 0 | J7: =+IF(AND(CALCULO!J7<>"", CALCULO!J7>0), CALCULO!J7, 0) -> 0 | K7: =+IF(AND(CALCULO!K7<>"", CALCULO!K7>0), CALCULO!K7, 0) -> 0 | L7: =+IF(AND(CALCULO!L7<>"", CALCULO!L7>0), CALCULO!L7, 0) -> 0 | M7: =+IF(AND(CALCULO!M7<>"", CALCULO!M7>0), CALCULO!M7, 0) -> 0 | ... AW7: =+IF(AND(CALCULO!AW7<>"", CALCULO!AW7>0), CALCULO!AW7, 0) -> 0 | BE7: =+IF(AND(CALCULO!AV7<>"", CALCULO!AV7>0), CALCULO!AV7, "0") -> 0
C8: =+SUM(F8:AM8) -> 0 | D8: =+IF(AND(CALCULO!D8<>"", CALCULO!D8>0), CALCULO!D8, "") | E8: =+IF(AND(CALCULO!E8<>"", CALCULO!E8>0), CALCULO!E8, "") | F8: =+IF(AND(CALCULO!F8<>"", CALCULO!F8>0), CALCULO!F8, 0) -> 0 | G8: =+IF(AND(CALCULO!G8<>"", CALCULO!G8>0), CALCULO!G8, 0) -> 0 | H8: =+IF(AND(CALCULO!H8<>"", CALCULO!H8>0), CALCULO!H8, 0) -> 0 | I8: =+IF(AND(CALCULO!I8<>"", CALCULO!I8>0), CALCULO!I8, 0) -> 0 | J8: =+IF(AND(CALCULO!J8<>"", CALCULO!J8>0), CALCULO!J8, 0) -> 0 | K8: =+IF(AND(CALCULO!K8<>"", CALCULO!K8>0), CALCULO!K8, 0) -> 0 | L8: =+IF(AND(CALCULO!L8<>"", CALCULO!L8>0), CALCULO!L8, 0) -> 0 | M8: =+IF(AND(CALCULO!M8<>"", CALCULO!M8>0), CALCULO!M8, 0) -> 0 | ... AW8: =+IF(AND(CALCULO!AW8<>"", CALCULO!AW8>0), CALCULO!AW8, 0) -> 0
C9: =+SUM(F9:AM9) -> 0 | D9: =+IF(AND(CALCULO!D9<>"", CALCULO!D9>0), CALCULO!D9, "") | E9: =+IF(AND(CALCULO!E9<>"", CALCULO!E9>0), CALCULO!E9, "") | F9: =+IF(AND(CALCULO!F9<>"", CALCULO!F9>0), CALCULO!F9, 0) -> 0 | G9: =+IF(AND(CALCULO!G9<>"", CALCULO!G9>0), CALCULO!G9, 0) -> 0 | H9: =+IF(AND(CALCULO!H9<>"", CALCULO!H9>0), CALCULO!H9, 0) -> 0 | I9: =+IF(AND(CALCULO!I9<>"", CALCULO!I9>0), CALCULO!I9, 0) -> 0 | J9: =+IF(AND(CALCULO!J9<>"", CALCULO!J9>0), CALCULO!J9, 0) -> 0 | K9: =+IF(AND(CALCULO!K9<>"", CALCULO!K9>0), CALCULO!K9, 0) -> 0 | L9: =+IF(AND(CALCULO!L9<>"", CALCULO!L9>0), CALCULO!L9, 0) -> 0 | M9: =+IF(AND(CALCULO!M9<>"", CALCULO!M9>0), CALCULO!M9, 0) -> 0 | ... AW9: =+IF(AND(CALCULO!AW9<>"", CALCULO!AW9>0), CALCULO!AW9, 0) -> 0
C10: =+SUM(F10:AM10) -> 0 | D10: =+IF(AND(CALCULO!D10<>"", CALCULO!D10>0), CALCULO!D10, "") | E10: =+IF(AND(CALCULO!E10<>"", CALCULO!E10>0), CALCULO!E10, "") | F10: =+IF(AND(CALCULO!F10<>"", CALCULO!F10>0), CALCULO!F10, 0) -> 0 | G10: =+IF(AND(CALCULO!G10<>"", CALCULO!G10>0), CALCULO!G10, 0) -> 0 | H10: =+IF(AND(CALCULO!H10<>"", CALCULO!H10>0), CALCULO!H10, 0) -> 0 | I10: =+IF(AND(CALCULO!I10<>"", CALCULO!I10>0), CALCULO!I10, 0) -> 0 | J10: =+IF(AND(CALCULO!J10<>"", CALCULO!J10>0), CALCULO!J10, 0) -> 0 | K10: =+IF(AND(CALCULO!K10<>"", CALCULO!K10>0), CALCULO!K10, 0) -> 0 | L10: =+IF(AND(CALCULO!L10<>"", CALCULO!L10>0), CALCULO!L10, 0) -> 0 | M10: =+IF(AND(CALCULO!M10<>"", CALCULO!M10>0), CALCULO!M10, 0) -> 0 | ... AW10: =+IF(AND(CALCULO!AW10<>"", CALCULO!AW10>0), CALCULO!AW10, 0) -> 0
C11: =+SUM(F11:AM11) -> 0 | D11: =+IF(AND(CALCULO!D11<>"", CALCULO!D11>0), CALCULO!D11, "") | E11: =+IF(AND(CALCULO!E11<>"", CALCULO!E11>0), CALCULO!E11, "") | F11: =+IF(AND(CALCULO!F11<>"", CALCULO!F11>0), CALCULO!F11, 0) -> 0 | G11: =+IF(AND(CALCULO!G11<>"", CALCULO!G11>0), CALCULO!G11, 0) -> 0 | H11: =+IF(AND(CALCULO!H11<>"", CALCULO!H11>0), CALCULO!H11, 0) -> 0 | I11: =+IF(AND(CALCULO!I11<>"", CALCULO!I11>0), CALCULO!I11, 0) -> 0 | J11: =+IF(AND(CALCULO!J11<>"", CALCULO!J11>0), CALCULO!J11, 0) -> 0 | K11: =+IF(AND(CALCULO!K11<>"", CALCULO!K11>0), CALCULO!K11, 0) -> 0 | L11: =+IF(AND(CALCULO!L11<>"", CALCULO!L11>0), CALCULO!L11, 0) -> 0 | M11: =+IF(AND(CALCULO!M11<>"", CALCULO!M11>0), CALCULO!M11, 0) -> 0 | ... AW11: =+IF(AND(CALCULO!AW11<>"", CALCULO!AW11>0), CALCULO!AW11, 0) -> 0
A12: ABUSO SEXUAL | C12: =+SUM(F12:AM12) -> 0 | E12: =+IF(AND(CALCULO!E12<>"", CALCULO!E12>0), CALCULO!E12, "") | F12: =+IF(AND(CALCULO!F12<>"", CALCULO!F12>0), CALCULO!F12, 0) -> 0 | G12: =+IF(AND(CALCULO!G12<>"", CALCULO!G12>0), CALCULO!G12, 0) -> 0 | H12: =+IF(AND(CALCULO!H12<>"", CALCULO!H12>0), CALCULO!H12, 0) -> 0 | I12: =+IF(AND(CALCULO!I12<>"", CALCULO!I12>0), CALCULO!I12, 0) -> 0 | J12: =+IF(AND(CALCULO!J12<>"", CALCULO!J12>0), CALCULO!J12, 0) -> 0 | K12: =+IF(AND(CALCULO!K12<>"",CALCULO!K12>0),CALCULO!K12,0) -> 0 | L12: =+IF(AND(CALCULO!L12<>"", CALCULO!L12>0), CALCULO!L12, 0) -> 0 | M12: =+IF(AND(CALCULO!M12<>"", CALCULO!M12>0), CALCULO!M12, 0) -> 0 | N12: =+IF(AND(CALCULO!N12<>"", CALCULO!N12>0), CALCULO!N12, 0) -> 0 | O12: =+IF(AND(CALCULO!O12<>"", CALCULO!O12>0), CALCULO!O12, 0) -> 0 | P12: =+IF(AND(CALCULO!P12<>"", CALCULO!P12>0), CALCULO!P12, 0) -> 0 | Q12: =+IF(AND(CALCULO!Q12<>"", CALCULO!Q12>0), CALCULO!Q12, 0) -> 0 | R12: =+IF(AND(CALCULO!R12<>"", CALCULO!R12>0), CALCULO!R12, 0) -> 0 | S12: =+IF(AND(CALCULO!S12<>"", CALCULO!S12>0), CALCULO!S12, 0) -> 0 | ... AQ12: =+IF(AND(CALCULO!AQ12<>"", CALCULO!AQ12>0), CALCULO!AQ12, 0) -> 0 | AR12: =+IF(AND(CALCULO!AT12<>"", CALCULO!AT12>0), CALCULO!AT12, 0) -> 0 | AS12: =+IF(AND(CALCULO!AU12<>"", CALCULO!AU12>0), CALCULO!AU12, 0) -> 0 | AT12: =+IF(AND(CALCULO!AR12<>"", CALCULO!AR12>0), CALCULO!AR12, 0) -> 0 | AU12: =+IF(AND(CALCULO!AS12<>"", CALCULO!AS12>0), CALCULO!AS12, 0) -> 0 | AV12: =+IF(AND(CALCULO!AW12<>"", CALCULO!AW12>0), CALCULO!AW12, 0) -> 0 | AW12: =+IF(AND(CALCULO!AX12<>"", CALCULO!AX12>0), CALCULO!AX12, 0) -> 0 | BE12: =+IF(AND(CALCULO!AV12<>"", CALCULO!AV12>0), CALCULO!AV12, "0") -> 0
A13: SUICIDIO | B13: IDEACIÓN | C13: =+SUM(F13:AM13) -> 0 | E13: =+IF(AND(CALCULO!E13<>"", CALCULO!E13>0), CALCULO!E13, "") | F13: =+IF(AND(CALCULO!F13<>"", CALCULO!F13>0), CALCULO!F13, 0) -> 0 | G13: =+IF(AND(CALCULO!G13<>"", CALCULO!G13>0), CALCULO!G13, 0) -> 0 | H13: =+IF(AND(CALCULO!H13<>"", CALCULO!H13>0), CALCULO!H13, 0) -> 0 | I13: =+IF(AND(CALCULO!I13<>"", CALCULO!I13>0), CALCULO!I13, 0) -> 0 | J13: =+IF(AND(CALCULO!J13<>"", CALCULO!J13>0), CALCULO!J13, 0) -> 0 | K13: =+IF(AND(CALCULO!K13<>"",CALCULO!K13>0),CALCULO!K13,0) -> 0 | L13: =+IF(AND(CALCULO!L13<>"", CALCULO!L13>0), CALCULO!L13, 0) -> 0 | M13: =+IF(AND(CALCULO!M13<>"", CALCULO!M13>0), CALCULO!M13, 0) -> 0 | N13: =+IF(AND(CALCULO!N13<>"", CALCULO!N13>0), CALCULO!N13, 0) -> 0 | O13: =+IF(AND(CALCULO!O13<>"", CALCULO!O13>0), CALCULO!O13, 0) -> 0 | P13: =+IF(AND(CALCULO!P13<>"", CALCULO!P13>0), CALCULO!P13, 0) -> 0 | Q13: =+IF(AND(CALCULO!Q13<>"", CALCULO!Q13>0), CALCULO!Q13, 0) -> 0 | R13: =+IF(AND(CALCULO!R13<>"", CALCULO!R13>0), CALCULO!R13, 0) -> 0 | S13: =+IF(AND(CALCULO!S13<>"", CALCULO!S13>0), CALCULO!S13, 0) -> 0 | ... AQ13: =+IF(AND(CALCULO!AQ13<>"", CALCULO!AQ13>0), CALCULO!AQ13, 0) -> 0 | AR13: =+IF(AND(CALCULO!AT13<>"", CALCULO!AT13>0), CALCULO!AT13, 0) -> 0 | AS13: =+IF(AND(CALCULO!AU13<>"", CALCULO!AU13>0), CALCULO!AU13, 0) -> 0 | AT13: =+IF(AND(CALCULO!AR13<>"", CALCULO!AR13>0), CALCULO!AR13, 0) -> 0 | AU13: =+IF(AND(CALCULO!AS13<>"", CALCULO!AS13>0), CALCULO!AS13, 0) -> 0 | AV13: =+IF(AND(CALCULO!AW13<>"", CALCULO!AW13>0), CALCULO!AW13, 0) -> 0 | AW13: =+IF(AND(CALCULO!AX13<>"", CALCULO!AX13>0), CALCULO!AX13, 0) -> 0 | BE13: =+IF(AND(CALCULO!AV13<>"", CALCULO!AV13>0), CALCULO!AV13, "0") -> 0
B14: INTENTO | C14: =+SUM(F14:AM14) -> 3 | E14: =+IF(AND(CALCULO!E14<>"", CALCULO!E14>0), CALCULO!E14, "") -> 2 | F14: =+IF(AND(CALCULO!F14<>"", CALCULO!F14>0), CALCULO!F14, 0) -> 0 | G14: =+IF(AND(CALCULO!G14<>"", CALCULO!G14>0), CALCULO!G14, 0) -> 0 | H14: =+IF(AND(CALCULO!H14<>"", CALCULO!H14>0), CALCULO!H14, 0) -> 0 | I14: =+IF(AND(CALCULO!I14<>"", CALCULO!I14>0), CALCULO!I14, 0) -> 0 | J14: =+IF(AND(CALCULO!J14<>"", CALCULO!J14>0), CALCULO!J14, 0) -> 0 | K14: =+IF(AND(CALCULO!K14<>"",CALCULO!K14>0),CALCULO!K14,0) -> 0 | L14: =+IF(AND(CALCULO!L14<>"", CALCULO!L14>0), CALCULO!L14, 0) -> 0 | M14: =+IF(AND(CALCULO!M14<>"", CALCULO!M14>0), CALCULO!M14, 0) -> 1 | N14: =+IF(AND(CALCULO!N14<>"", CALCULO!N14>0), CALCULO!N14, 0) -> 0 | O14: =+IF(AND(CALCULO!O14<>"", CALCULO!O14>0), CALCULO!O14, 0) -> 0 | P14: =+IF(AND(CALCULO!P14<>"", CALCULO!P14>0), CALCULO!P14, 0) -> 0 | Q14: =+IF(AND(CALCULO!Q14<>"", CALCULO!Q14>0), CALCULO!Q14, 0) -> 0 | R14: =+IF(AND(CALCULO!R14<>"", CALCULO!R14>0), CALCULO!R14, 0) -> 0 | S14: =+IF(AND(CALCULO!S14<>"", CALCULO!S14>0), CALCULO!S14, 0) -> 0 | ... AQ14: =+IF(AND(CALCULO!AQ14<>"", CALCULO!AQ14>0), CALCULO!AQ14, 0) -> 0 | AR14: =+IF(AND(CALCULO!AT14<>"", CALCULO!AT14>0), CALCULO!AT14, 0) -> 0 | AS14: =+IF(AND(CALCULO!AU14<>"", CALCULO!AU14>0), CALCULO!AU14, 0) -> 0 | AT14: =+IF(AND(CALCULO!AR14<>"", CALCULO!AR14>0), CALCULO!AR14, 0) -> 0 | AU14: =+IF(AND(CALCULO!AS14<>"", CALCULO!AS14>0), CALCULO!AS14, 0) -> 0 | AV14: =+IF(AND(CALCULO!AW14<>"", CALCULO!AW14>0), CALCULO!AW14, 0) -> 0 | AW14: =+IF(AND(CALCULO!AX14<>"", CALCULO!AX14>0), CALCULO!AX14, 0) -> 0 | BE14: =+IF(AND(CALCULO!AV14<>"", CALCULO!AV14>0), CALCULO!AV14, "0") -> 1
A15: PERSONAS CON DIAGNOSTICOS DE TRASTORNOS MENTALES | C15: =+SUM(F15:AM15) -> 79 | F15: =+IF(AND(CALCULO!F15<>"", CALCULO!F15>0), CALCULO!F15, 0) -> 0 | G15: =+IF(AND(CALCULO!G15<>"", CALCULO!G15>0), CALCULO!G15, 0) -> 0 | H15: =+IF(AND(CALCULO!H15<>"", CALCULO!H15>0), CALCULO!H15, 0) -> 0 | I15: =+IF(AND(CALCULO!I15<>"", CALCULO!I15>0), CALCULO!I15, 0) -> 0 | J15: =+IF(AND(CALCULO!J15<>"", CALCULO!J15>0), CALCULO!J15, 0) -> 0 | K15: =+IF(AND(CALCULO!K15<>"",CALCULO!K15>0),CALCULO!K15,0) -> 0 | L15: =+IF(AND(CALCULO!L15<>"", CALCULO!L15>0), CALCULO!L15, 0) -> 0 | M15: =+IF(AND(CALCULO!M15<>"", CALCULO!M15>0), CALCULO!M15, 0) -> 11 | N15: =+IF(AND(CALCULO!N15<>"", CALCULO!N15>0), CALCULO!N15, 0) -> 1 | O15: =+IF(AND(CALCULO!O15<>"", CALCULO!O15>0), CALCULO!O15, 0) -> 0 | P15: =+IF(AND(CALCULO!P15<>"", CALCULO!P15>0), CALCULO!P15, 0) -> 0 | Q15: =+IF(AND(CALCULO!Q15<>"", CALCULO!Q15>0), CALCULO!Q15, 0) -> 6 | R15: =+IF(AND(CALCULO!R15<>"", CALCULO!R15>0), CALCULO!R15, 0) -> 0 | S15: =+IF(AND(CALCULO!S15<>"", CALCULO!S15>0), CALCULO!S15, 0) -> 0 | ... AQ15: =+IF(AND(CALCULO!AQ15<>"", CALCULO!AQ15>0), CALCULO!AQ15, 0) -> 6 | AR15: =+IF(AND(CALCULO!AT15<>"", CALCULO!AT15>0), CALCULO!AT15, 0) -> 0 | AS15: =+IF(AND(CALCULO!AU15<>"", CALCULO!AU15>0), CALCULO!AU15, 0) -> 0 | AT15: =+IF(AND(CALCULO!AR15<>"", CALCULO!AR15>0), CALCULO!AR15, 0) -> 0 | AU15: =+IF(AND(CALCULO!AS15<>"", CALCULO!AS15>0), CALCULO!AS15, 0) -> 0 | AV15: =+IF(AND(CALCULO!AW15<>"", CALCULO!AW15>0), CALCULO!AW15, 0) -> 1 | AW15: =+IF(AND(CALCULO!AX15<>"", CALCULO!AX15>0), CALCULO!AX15, 0) -> 0 | BE15: =+IF(AND(CALCULO!AV15<>"", CALCULO!AV15>0), CALCULO!AV15, "0") -> 2
